Workbook
Name ColumnTitle1: #REF!
Name RowTitleRegion1..E2: '[1]Factory IDs'!#REF!
Name RowTitleRegion2..I2: '[1]Factory IDs'!#REF!
Name RowTitleRegion4..I8: '[1]Factory IDs'!#REF!

Sheet Energy n product
C2: 122 | D2: 8 | E2: 9 | F2: 10 | G2: 11 | H2: 12 | I2: 120 | J2: 121 | K2: 13 | L2: 14 | M2: 15 | N2: 16 | O2: 17 | P2: 18 | Q2: 20 | R2: 19 | S2: 21 | T2: 22 | U2: 23 | V2: 24 | W2: 25 | X2: 26 | Y2: 27 | Z2: 28 | AA2: 29 | AB2: 30 | AC2: 31 | AD2: 32 | AE2: 33 | AF2: 34 | AG2: 35 | AH2: 36 | AI2: 37 | AJ2: 38 | AK2: 39 | AL2: 40 | AM2: 41 | AN2: 42 | AO2: 43 | AP2: 44 | AQ2: 59 | AR2: 60 | AS2: 61 | AT2: 62 | AU2: 63 | AV2: 58 | AW2: 64 | AX2: 65 | AY2: 66 | AZ2: 67
B5: Bảng tổng hợp | C5: Total Product | D5: Electricity consumption (kWh)用电量 Lượng điện tiêu thụ | S5: Coal 煤的 Than - Lò hơi | W5: Nhiên liệu sinh khối Biomass 生物质能 | AA5: Petrol for Car汽车汽油 Xăng cho ô tô | AE5: Diesel for car汽车柴油 Dầu cho ô tô | AI5: Diesel for forklift叉车柴油 - Dầu cho xe nâng | AM5: Gas for canteen餐厅燃气Gas dùng cho nhà ăn | AQ5: Cost ($) | AR5: MJ | AS5: Scope 1 | AT5: Scope 2 | AU5: Scope 3 | AV5: Offset CO2 | AW5: KPIs
C6: Total Product | D6: SCOPE 2 | H6: SCOPE 2 | N6: SCOPE 1 | S6: SCOPE 1 | AA6: SCOPE 1 | AE6: SCOPE 1 | AI6: SCOPE 1 | AM6: SCOPE 1 | AU6: Category 5 | AV6: Offset CO2 | AW6: Tổng sản lượng ( theo tấn, đôi, cái…)
B7: # | C7: Total Products (Pairs) 总产量 Tổng sản lượng ( theo tấn, đôi, cái…) | D7: Electricity consumption from EVN (kWh) 用电量 Lượng điện tiêu thụ | E7: Cost of electricity from EVN (VNĐ) 金额 Tiền điện (VNĐ) | F7: Nhiệt trị (MJ) HHV - Gross Calorific Value (MJ/kg) 总热值 | G7: Lượng phát thải CO2 emission (kg) CO2二氧化碳排放 | H7: Electricity consumption from Solar Mua điện mặt trời (kWh) | I7: Nhiệt trị (MJ) HHV - Gross Calorific Value (MJ/kg) 总热值 | J7: Offset CO2 (kg) CO2 | K7: Solar Electricity cost Chi phí mua điện mặt trời (VND) | L7: Solar electricity sell to grid Điện mặt trời công ty bán lên lưới (kWh) | M7: Electricity money sell to grid Tiền bán điện mặt trời nối lưới (VND) | N7: Generated (kWh) 发电量 Lượng điện từ máy phát điện (kWh) | O7: DO consumption for generator (Lit) 柴油使用量 Lượng dầu diezel sử dụng cho máy phát điện (Lít) | P7: Cost of generated (VNĐ 金额 Tiền dầu cho máy phát điện(VNĐ) | Q7: Nhiệt trị (MJ) HHV - Gross Calorific Value (MJ/kg) 总热值 | R7: Lượng phát thải CO2 emission (kg) CO2二氧化碳排放 | S7: Coal consumption (Tấn) 煤的使用量 Lượng than sử dụng (Tấn) | T7: Coal used (VNĐ) 金额 Tiền Than (VNĐ | U7: Nhiệt trị (MJ) HHV - Gross Calorific Value (MJ/kg) 总热值 | V7: Lượng phát thải CO2 emission (kg) CO2二氧化碳排放 | W7: 生物质能 Trấu đốt sử dụng (Tấn) Cost of Rice husk consumption (Tấn) | X7: 生物质能 Tổng chi phí nhiên liệu sinh khối Total biomass consumption (Kg) | Y7: Nhiệt trị (MJ) HHV - Gross Calorific Value (MJ/kg) 总热值 | Z7: Lượng phát thải CO2 emission (kg) CO2二氧化碳排放 | AA7: Oil consumption for car (L) 汽油使用量 Lượng xăng sử dụng (L) | AB7: Cost of oil for car (USD) 金额 Tiền xăng cho xe ô tô (VNĐ | AC7: Nhiệt trị (MJ) HHV - Gross Calorific Value (MJ/kg) 总热值 | AD7: Lượng phát thải CO2 emission (kg) CO2二氧化碳排放 | AE7: Diesel consumption for car (L) 汽车柴油使用量 Lượng dầu diezel sử dụng cho ô tô | AF7: Cost of diesel for car (USD) 金额 Tiền dầu cho xe oto (VNĐ) | AG7: Nhiệt trị (MJ) HHV - Gross Calorific Value (MJ/kg) 总热值 | AH7: Lượng phát thải CO2 emission (kg) CO2二氧化碳排放 | AI7: Diesel consumption for forklift (L)叉车柴油使用量 Lượng dầu diezel sử dụng cho xe nâng (L) | AJ7: Cost of diesel for forklift (VNĐ) 金额 Tiền dầu cho xe nâng (VNĐ) | AK7: Nhiệt trị (MJ) HHV - Gross Calorific Value (MJ/kg) 总热值 | AL7: Lượng phát thải CO2 emission (kg) CO2二氧化碳排放 | AM7: Gas consumption (kg) 燃气使用量 Lượng gas sử dụng (Kg) | AN7: Chi phí mua gas (VNĐ) Cost of Gas (VNĐ 金额 Tiền mua Gas (VNĐ) | AO7: Nhiệt trị (MJ) HHV - Gross Calorific Value (MJ/kg) 总热值 | AP7: Lượng phát thải CO2 emission (kg) CO2二氧化碳排放 | AQ7: Total energy cost (US$) 总共能源费用 Tổng chi phí năng lượng (VNĐ) | AR7: Total energy consumption (MJ) 总共能源用量 Tổng năng lượng sử dụng (MJ) | AS7: Lượng phát thải CO2 emission (kg) CO2二氧化碳排放 | AT7: Lượng phát thải CO2 emission (kg) CO2二氧化碳排放 | AU7: Lượng phát thải CO2 emission (kg) CO2二氧化碳排放 | AV7: Offset CO2 (kg) CO2 | AW7: KPI -1 Năng lượng/sản phẩm MJ/SP | AX7: KPI -2 Energy cost /SP (VNĐ/SP) Chi phí năng lượng/SP | AY7: Lượng phát thải CO2/SP emission (kg) CO2二氧化碳排放 | AZ7: Tonne oil equivalent (TOE) Tấn dầu quy đổi tương đương (TOE)
B8: 1 | F8: =D8*3.6 -> 0 | G8: =D8*0.7221 -> 0 | I8: =H8*3.6 -> 0 | J8: =H8*0.7221 -> 0 | N8: =C22 -> 0 | O8: =D22 -> 0 | P8: =E22 -> 0 | Q8: =I22 -> 0 | R8: =J22 -> 0 | S8: =C35 -> 0 | T8: =D35 -> 0 | U8: =H35 -> 0 | V8: =I35 -> 0 | W8: =C52 -> 0 | X8: =D52 -> 0 | Y8: =H52 -> 0 | Z8: =I52 -> 0 | AA8: =C67 -> 0 | AB8: =D67 -> 0 | AC8: =H67 -> 0 | AD8: =I67 -> 0 | AG8: =AE8*36.8 -> 0 | AH8: =AE8*2.7 -> 0 | AK8: =AI8*36.8 -> 0 | AL8: =AI8*2.7 -> 0 | AM8: =C82 -> 0 | AN8: =D82 -> 0 | AO8: =H82 -> 0 | AP8: =I82 -> 0 | AQ8: =E8+K8+O8+T8+X8+AB8+AF8+AJ8+AN8 -> 0 | AR8: =AO8+AK8+AG8+AC8+Y8+U8+R8+F8 -> 0 | AS8: =R8+V8+AD8+AH8+AL8+AP8 -> 0 | AT8: =G8 -> 0 | AU8: =Waste!Q9 -> 0 | AW8: =IFERROR(AR8/C8,0) -> 0 | AX8: =IFERROR(AQ8/C8,0) -> 0 | AY8: =IFERROR((AS8+AT8)/C8,0) -> 0 | AZ8: =AR8/41868 -> 0
B21: IT | C21: 16 | D21: 17 | E21: 18 | I21: 20 | J21: 19
C22: =SUM(C26:C33) -> 0 | D22: =SUM(D26:D33) -> 0 | E22: =SUM(E26:E33) -> 0 | F22: =SUM(F26:F33) -> 0 | G22: =SUM(G26:G33) -> 0 | H22: =SUM(H26:H33) -> 0 | I22: =SUM(I26:I33) -> 0 | J22: =SUM(J26:J33) -> 0
C24: Energy - dầu - phát điện
B25: # | C25: Generated (kWh) 发电量 Lượng điện từ máy phát điện (kWh) | D25: DO consumption for generator (Lit) 柴油使用量 Lượng dầu diezel sử dụng cho máy phát điện (Lít) | E25: Cost of generated (VNĐ 金额 Tiền dầu cho máy phát điện(VNĐ) | F25: Loai dầu | G25: Hệ số nhiệt trị | H25: Hệ số CO2 | I25: Nhiệt trị (MJ) HHV - Gross Calorific Value (MJ/kg) 总热值 | J25: Lượng phát thải CO2 emission (kg) CO2二氧化碳排放
B26: 1 | G26: =IFERROR(VLOOKUP($F26,'Ref tables'!$C$4:$D$5,2,0),0) -> 0 | H26: =IFERROR(VLOOKUP($F26,'Ref tables'!$C$4:$E$5,3,0),0) -> 0 | I26: =G26*D26 -> 0 | J26: =D26*H26 -> 0
B27: 2 | G27: =IFERROR(VLOOKUP($F27,'Ref tables'!$C$4:$D$5,2,0),0) -> 0 | H27: =IFERROR(VLOOKUP($F27,'Ref tables'!$C$4:$E$5,3,0),0) -> 0 | I27: =G27*D27 -> 0 | J27: =D27*H27 -> 0
B28: 3 | G28: =IFERROR(VLOOKUP($F28,'Ref tables'!$C$4:$D$5,2,0),0) -> 0 | H28: =IFERROR(VLOOKUP($F28,'Ref tables'!$C$4:$E$5,3,0),0) -> 0 | I28: =G28*D28 -> 0 | J28: =D28*H28 -> 0
B29: 4 | G29: =IFERROR(VLOOKUP($F29,'Ref tables'!$C$4:$D$5,2,0),0) -> 0 | H29: =IFERROR(VLOOKUP($F29,'Ref tables'!$C$4:$E$5,3,0),0) -> 0 | I29: =G29*D29 -> 0 | J29: =D29*H29 -> 0
B30: 5 | G30: =IFERROR(VLOOKUP($F30,'Ref tables'!$C$4:$D$5,2,0),0) -> 0 | H30: =IFERROR(VLOOKUP($F30,'Ref tables'!$C$4:$E$5,3,0),0) -> 0 | I30: =G30*D30 -> 0 | J30: =D30*H30 -> 0
B31: 6 | G31: =IFERROR(VLOOKUP($F31,'Ref tables'!$C$4:$D$5,2,0),0) -> 0 | H31: =IFERROR(VLOOKUP($F31,'Ref tables'!$C$4:$E$5,3,0),0) -> 0 | I31: =G31*D31 -> 0 | J31: =D31*H31 -> 0
B32: 7 | G32: =IFERROR(VLOOKUP($F32,'Ref tables'!$C$4:$D$5,2,0),0) -> 0 | H32: =IFERROR(VLOOKUP($F32,'Ref tables'!$C$4:$E$5,3,0),0) -> 0 | I32: =G32*D32 -> 0 | J32: =D32*H32 -> 0
B33: 8 | G33: =IFERROR(VLOOKUP($F33,'Ref tables'!$C$4:$D$5,2,0),0) -> 0 | H33: =IFERROR(VLOOKUP($F33,'Ref tables'!$C$4:$E$5,3,0),0) -> 0 | I33: =G33*D33 -> 0 | J33: =D33*H33 -> 0
B34: IT | C34: 21 | D34: 22 | H34: 23 | I34: 24
C35: =SUM(C39:C50) -> 0 | D35: =SUM(D39:D50) -> 0 | E35: =SUM(E39:E50) -> 0 | F35: =SUM(F39:F50) -> 0 | G35: =SUM(G39:G50) -> 0 | H35: =SUM(H39:H50) -> 0 | I35: =SUM(I39:I50) -> 0
C36: Coal 煤的 Than - Lò hơi
C37: SCOPE 1
B38: # | C38: Coal consumption (Tấn) 煤的使用量 Lượng than sử dụng (Tấn) | D38: Coal used (VNĐ) 金额 Tiền Than (VNĐ | E38: Loại than | F38: Hệ số nhiệt trị | G38: Hệ số CO2 | H38: Nhiệt trị (MJ) HHV - Gross Calorific Value (MJ) 总热值 | I38: Lượng phát thải CO2 emission (kg) CO2二氧化碳排放
B39: 1 | F39: =IFERROR(VLOOKUP($E39,'Ref tables'!$G$4:$I$9,2,0),0) -> 0 | G39: =IFERROR(VLOOKUP($E39,'Ref tables'!$G$4:$I$9,3,0),0) -> 0 | H39: =F39*C39 -> 0 | I39: =C39*G39 -> 0
B40: 2 | F40: =IFERROR(VLOOKUP($E40,'Ref tables'!$G$4:$I$9,2,0),0) -> 0 | G40: =IFERROR(VLOOKUP($E40,'Ref tables'!$G$4:$I$9,3,0),0) -> 0 | H40: =F40*C40 -> 0 | I40: =C40*G40 -> 0
B41: 3 | F41: =IFERROR(VLOOKUP($E41,'Ref tables'!$G$4:$I$9,2,0),0) -> 0 | G41: =IFERROR(VLOOKUP($E41,'Ref tables'!$G$4:$I$9,3,0),0) -> 0 | H41: =F41*C41 -> 0 | I41: =C41*G41 -> 0
B42: 4 | F42: =IFERROR(VLOOKUP($E42,'Ref tables'!$G$4:$I$9,2,0),0) -> 0 | G42: =IFERROR(VLOOKUP($E42,'Ref tables'!$G$4:$I$9,3,0),0) -> 0 | H42: =F42*C42 -> 0 | I42: =C42*G42 -> 0
B43: 5 | F43: =IFERROR(VLOOKUP($E43,'Ref tables'!$G$4:$I$9,2,0),0) -> 0 | G43: =IFERROR(VLOOKUP($E43,'Ref tables'!$G$4:$I$9,3,0),0) -> 0 | H43: =F43*C43 -> 0 | I43: =C43*G43 -> 0
B44: 6 | F44: =IFERROR(VLOOKUP($E44,'Ref tables'!$G$4:$I$9,2,0),0) -> 0 | G44: =IFERROR(VLOOKUP($E44,'Ref tables'!$G$4:$I$9,3,0),0) -> 0 | H44: =F44*C44 -> 0 | I44: =C44*G44 -> 0
B45: 7 | F45: =IFERROR(VLOOKUP($E45,'Ref tables'!$G$4:$I$9,2,0),0) -> 0 | G45: =IFERROR(VLOOKUP($E45,'Ref tables'!$G$4:$I$9,3,0),0) -> 0 | H45: =F45*C45 -> 0 | I45: =C45*G45 -> 0
B46: 8 | F46: =IFERROR(VLOOKUP($E46,'Ref tables'!$G$4:$I$9,2,0),0) -> 0 | G46: =IFERROR(VLOOKUP($E46,'Ref tables'!$G$4:$I$9,3,0),0) -> 0 | H46: =F46*C46 -> 0 | I46: =C46*G46 -> 0
B47: 9 | F47: =IFERROR(VLOOKUP($E47,'Ref tables'!$G$4:$I$9,2,0),0) -> 0 | G47: =IFERROR(VLOOKUP($E47,'Ref tables'!$G$4:$I$9,3,0),0) -> 0 | H47: =F47*C47 -> 0 | I47: =C47*G47 -> 0
B48: 10 | F48: =IFERROR(VLOOKUP($E48,'Ref tables'!$G$4:$I$9,2,0),0) -> 0 | G48: =IFERROR(VLOOKUP($E48,'Ref tables'!$G$4:$I$9,3,0),0) -> 0 | H48: =F48*C48 -> 0 | I48: =C48*G48 -> 0
B49: 11 | F49: =IFERROR(VLOOKUP($E49,'Ref tables'!$G$4:$I$9,2,0),0) -> 0 | G49: =IFERROR(VLOOKUP($E49,'Ref tables'!$G$4:$I$9,3,0),0) -> 0 | H49: =F49*C49 -> 0 | I49: =C49*G49 -> 0
B50: 12 | F50: =IFERROR(VLOOKUP($E50,'Ref tables'!$G$4:$I$9,2,0),0) -> 0 | G50: =IFERROR(VLOOKUP($E50,'Ref tables'!$G$4:$I$9,3,0),0) -> 0 | H50: =F50*C50 -> 0 | I50: =C50*G50 -> 0
B51: IT | C51: 25 | D51: 26 | H51: 27 | I51: 28
C52: =SUM(C56:C65) -> 0 | D52: =SUM(D56:D65) -> 0 | E52: =SUM(E56:E65) -> 0 | F52: =SUM(F56:F65) -> 0 | G52: =SUM(G56:G65) -> 0 | H52: =SUM(H56:H65) -> 0 | I52: =SUM(I56:I65) -> 0
C53: Nhiên liệu sinh khối Biomass 生物质能
C54: SCOPE 1
B55: # | C55: 生物质能 Trấu đốt sử dụng (Tấn) Cost of Rice husk consumption (Tấn) | D55: 生物质能 Tổng chi phí nhiên liệu sinh khối Total biomass consumption (Kg) | E55: Loại sinh khối | F55: Hệ số nhiệt trị | G55: Hệ số CO2 | H55: Nhiệt trị (MJ) HHV - Gross Calorific Value (MJ) 总热值 | I55: Lượng phát thải CO2 emission (kg) CO2二氧化碳排放
B56: 1 | F56: =IFERROR(VLOOKUP($E56,'Ref tables'!$L$4:$N$7,2,0),0) -> 0 | G56: =IFERROR(VLOOKUP($E56,'Ref tables'!$L$4:$N$7,3,0),0) -> 0 | H56: =F56*C56 -> 0 | I56: =C56*G56 -> 0
...

Sheet Waste
C2: 45 | D2: 46 | E2: 47 | F2: 48 | G2: 49 | H2: 50 | I2: 51 | J2: 52 | K2: 53 | L2: 54 | M2: 55 | N2: 56 | O2: 57 | P2: 123 | Q2: 124
B5: WASTE - DATA INPUT FORM
C7: Waste | G7: Waste treatment | Q7: SCOPE 3 - Category 5
B8: # | C8: Total solid waste Quantity (kg) Lượng chất thải rắn (Kg) | D8: Tổng lượng chất thải tái chế Recycle (Kg) | E8: Hazardous waste Quantity (Kg) Số lượng chất thải nguy hại 危险垃圾类 (Kg) | F8: Hazardous waste collection bill Hóa đơn thu gom xử lý chất thải nguy hại 处理费用 chi phí xử lý (VND) | G8: Landfill (kg) Chôn lấp (Kg) 掩埋 | H8: Lượng khí phát thải (Kg CO2) | I8: Incinerated Thiêu đốt 焚烧 (Kg) | J8: Lượng khí phát thải (Kg CO2) | K8: Composted Phân hủy hữu cơ (kg) | L8: Lượng khí phát thải (Kg CO2) | M8: Recycled - tái chế (kg) | N8: Lượng khí phát thải (Kg CO2) | O8: Loại Khác Others (Kg) | P8: Lượng khí phát thải (Kg CO2) | Q8: Tổng lượng khí phát thải (Kg CO2)
B9: 1 | G9: =B25 -> 0 | H9: =E25 -> 0 | I9: =G25 -> 0 | J9: =J25 -> 0 | K9: =L25 -> 0 | L9: =O25 -> 0 | M9: =Q25 -> 0 | N9: =T25 -> 0 | O9: =V25 -> 0 | P9: =Y25 -> 0 | Q9: =N9+L9+J9+H9+P9 -> 0
B10: Feb - Tháng 2
B11: Mar - Tháng 3
B12: Apr - Tháng 4
B13: May - Tháng 5
B14: Jun - Tháng 6
B15: Jul - Tháng 7
B16: Aug - Tháng 8
B17: Sep - Tháng 9
B18: Oct - Tháng 10
B19: Nov - Tháng 11
B20: Dec - Tháng 12
B21: Total - Tổng
Q22: ID50+ID52+ID54+ID56+ID123
B24: 49 | E24: 50 | G24: 51 | J24: 52 | L24: 53 | O24: 54 | Q24: 55 | T24: 56 | V24: 57 | Y24: 123
B25: =SUM(B27:B249) -> 0 | C25: =SUM(C27:C249) -> 0 | D25: =SUM(D27:D249) -> 0 | E25: =SUM(E27:E249) -> 0 | G25: =SUM(G27:G249) -> 0 | H25: =SUM(H27:H249) -> 0 | I25: =SUM(I27:I249) -> 0 | J25: =SUM(J27:J249) -> 0 | L25: =SUM(L27:L249) -> 0 | M25: =SUM(M27:M249) -> 0 | N25: =SUM(N27:N249) -> 0 | O25: =SUM(O27:O249) -> 0 | Q25: =SUM(Q27:Q249) -> 0 | R25: =SUM(R27:R249) -> 0 | S25: =SUM(S27:S249) -> 0 | T25: =SUM(T27:T249) -> 0 | V25: =SUM(V27:V249) -> 0 | W25: =SUM(W27:W249) -> 0 | X25: =SUM(X27:X249) -> 0 | Y25: =SUM(Y27:Y249) -> 0
B26: Landfill (kg) Chôn lấp (Kg) 掩埋 | C26: Loai | D26: Hệ số phát thải Emission factor (Kg CO2/Kg) | E26: Lượng khí phát thải (Kg CO2) | G26: Incinerated Thiêu đốt 焚烧 (Kg) | H26: Loai | I26: Hệ số phát thải Emission factor (Kg CO2/Kg) | J26: Lượng khí phát thải (Kg CO2) | L26: Composted Phân hủy hữu cơ (kg) | M26: Loai | N26: Hệ số phát thải Emission factor (Kg CO2/Kg) | O26: Lượng khí phát thải (Kg CO2) | Q26: Recycled - tái chế (kg) | R26: Loai | S26: Hệ số phát thải Emission factor (Kg CO2/Kg) | T26: Lượng khí phát thải (Kg CO2) | V26: Others - loại khác (kg) | W26: Loai | X26: Hệ số phát thải Emission factor (Kg CO2/Kg) | Y26: Lượng khí phát thải (Kg CO2)
D27: =IFERROR(VLOOKUP($C27,'Ref tables'!$C$18:$D$31,2,0),0) -> 0 | E27: =B27*D27 -> 0 | I27: =IFERROR(VLOOKUP($H27,'Ref tables'!$C$18:$D$31,2,0),0) -> 0 | J27: =G27*I27 -> 0 | N27: =IFERROR(VLOOKUP($M27,'Ref tables'!$C$18:$D$31,2,0),0) -> 0 | O27: =L27*N27 -> 0 | S27: =IFERROR(VLOOKUP($R27,'Ref tables'!$C$18:$D$31,2,0),0) -> 0 | T27: =Q27*S27 -> 0 | X27: =IFERROR(VLOOKUP($W27,'Ref tables'!$C$18:$D$31,2,0),0) -> 0 | Y27: =V27*X27 -> 0
D28: =IFERROR(VLOOKUP($C28,'Ref tables'!$C$18:$D$31,2,0),0) -> 0 | E28: =B28*D28 -> 0 | I28: =IFERROR(VLOOKUP($H28,'Ref tables'!$C$18:$D$31,2,0),0) -> 0 | J28: =G28*I28 -> 0 | N28: =IFERROR(VLOOKUP($M28,'Ref tables'!$C$18:$D$31,2,0),0) -> 0 | O28: =L28*N28 -> 0 | S28: =IFERROR(VLOOKUP($R28,'Ref tables'!$C$18:$D$31,2,0),0) -> 0 | T28: =Q28*S28 -> 0 | X28: =IFERROR(VLOOKUP($W28,'Ref tables'!$C$18:$D$31,2,0),0) -> 0 | Y28: =V28*X28 -> 0
D29: =IFERROR(VLOOKUP($C29,'Ref tables'!$C$18:$D$31,2,0),0) -> 0 | E29: =B29*D29 -> 0 | I29: =IFERROR(VLOOKUP($H29,'Ref tables'!$C$18:$D$31,2,0),0) -> 0 | J29: =G29*I29 -> 0 | N29: =IFERROR(VLOOKUP($M29,'Ref tables'!$C$18:$D$31,2,0),0) -> 0 | O29: =L29*N29 -> 0 | S29: =IFERROR(VLOOKUP($R29,'Ref tables'!$C$18:$D$31,2,0),0) -> 0 | T29: =Q29*S29 -> 0 | X29: =IFERROR(VLOOKUP($W29,'Ref tables'!$C$18:$D$31,2,0),0) -> 0 | Y29: =V29*X29 -> 0
D30: =IFERROR(VLOOKUP($C30,'Ref tables'!$C$18:$D$31,2,0),0) -> 0 | E30: =B30*D30 -> 0 | I30: =IFERROR(VLOOKUP($H30,'Ref tables'!$C$18:$D$31,2,0),0) -> 0 | J30: =G30*I30 -> 0 | N30: =IFERROR(VLOOKUP($M30,'Ref tables'!$C$18:$D$31,2,0),0) -> 0 | O30: =L30*N30 -> 0 | S30: =IFERROR(VLOOKUP($R30,'Ref tables'!$C$18:$D$31,2,0),0) -> 0 | T30: =Q30*S30 -> 0 | X30: =IFERROR(VLOOKUP($W30,'Ref tables'!$C$18:$D$31,2,0),0) -> 0 | Y30: =V30*X30 -> 0
D31: =IFERROR(VLOOKUP($C31,'Ref tables'!$C$18:$D$31,2,0),0) -> 0 | E31: =B31*D31 -> 0 | I31: =IFERROR(VLOOKUP($H31,'Ref tables'!$C$18:$D$31,2,0),0) -> 0 | J31: =G31*I31 -> 0 | N31: =IFERROR(VLOOKUP($M31,'Ref tables'!$C$18:$D$31,2,0),0) -> 0 | O31: =L31*N31 -> 0 | S31: =IFERROR(VLOOKUP($R31,'Ref tables'!$C$18:$D$31,2,0),0) -> 0 | T31: =Q31*S31 -> 0 | X31: =IFERROR(VLOOKUP($W31,'Ref tables'!$C$18:$D$31,2,0),0) -> 0 | Y31: =V31*X31 -> 0
D32: =IFERROR(VLOOKUP($C32,'Ref tables'!$C$18:$D$31,2,0),0) -> 0 | E32: =B32*D32 -> 0 | I32: =IFERROR(VLOOKUP($H32,'Ref tables'!$C$18:$D$31,2,0),0) -> 0 | J32: =G32*I32 -> 0 | N32: =IFERROR(VLOOKUP($M32,'Ref tables'!$C$18:$D$31,2,0),0) -> 0 | O32: =L32*N32 -> 0 | S32: =IFERROR(VLOOKUP($R32,'Ref tables'!$C$18:$D$31,2,0),0) -> 0 | T32: =Q32*S32 -> 0 | X32: =IFERROR(VLOOKUP($W32,'Ref tables'!$C$18:$D$31,2,0),0) -> 0 | Y32: =V32*X32 -> 0
D33: =IFERROR(VLOOKUP($C33,'Ref tables'!$C$18:$D$31,2,0),0) -> 0 | E33: =B33*D33 -> 0 | I33: =IFERROR(VLOOKUP($H33,'Ref tables'!$C$18:$D$31,2,0),0) -> 0 | J33: =G33*I33 -> 0 | N33: =IFERROR(VLOOKUP($M33,'Ref tables'!$C$18:$D$31,2,0),0) -> 0 | O33: =L33*N33 -> 0 | S33: =IFERROR(VLOOKUP($R33,'Ref tables'!$C$18:$D$31,2,0),0) -> 0 | T33: =Q33*S33 -> 0 | X33: =IFERROR(VLOOKUP($W33,'Ref tables'!$C$18:$D$31,2,0),0) -> 0 | Y33: =V33*X33 -> 0
D34: =IFERROR(VLOOKUP($C34,'Ref tables'!$C$18:$D$31,2,0),0) -> 0 | E34: =B34*D34 -> 0 | I34: =IFERROR(VLOOKUP($H34,'Ref tables'!$C$18:$D$31,2,0),0) -> 0 | J34: =G34*I34 -> 0 | N34: =IFERROR(VLOOKUP($M34,'Ref tables'!$C$18:$D$31,2,0),0) -> 0 | O34: =L34*N34 -> 0 | S34: =IFERROR(VLOOKUP($R34,'Ref tables'!$C$18:$D$31,2,0),0) -> 0 | T34: =Q34*S34 -> 0 | X34: =IFERROR(VLOOKUP($W34,'Ref tables'!$C$18:$D$31,2,0),0) -> 0 | Y34: =V34*X34 -> 0
D35: =IFERROR(VLOOKUP($C35,'Ref tables'!$C$18:$D$31,2,0),0) -> 0 | E35: =B35*D35 -> 0 | I35: =IFERROR(VLOOKUP($H35,'Ref tables'!$C$18:$D$31,2,0),0) -> 0 | J35: =G35*I35 -> 0 | N35: =IFERROR(VLOOKUP($M35,'Ref tables'!$C$18:$D$31,2,0),0) -> 0 | O35: =L35*N35 -> 0 | S35: =IFERROR(VLOOKUP($R35,'Ref tables'!$C$18:$D$31,2,0),0) -> 0 | T35: =Q35*S35 -> 0 | X35: =IFERROR(VLOOKUP($W35,'Ref tables'!$C$18:$D$31,2,0),0) -> 0 | Y35: =V35*X35 -> 0
D36: =IFERROR(VLOOKUP($C36,'Ref tables'!$C$18:$D$31,2,0),0) -> 0 | E36: =B36*D36 -> 0 | I36: =IFERROR(VLOOKUP($H36,'Ref tables'!$C$18:$D$31,2,0),0) -> 0 | J36: =G36*I36 -> 0 | N36: =IFERROR(VLOOKUP($M36,'Ref tables'!$C$18:$D$31,2,0),0) -> 0 | O36: =L36*N36 -> 0 | S36: =IFERROR(VLOOKUP($R36,'Ref tables'!$C$18:$D$31,2,0),0) -> 0 | T36: =Q36*S36 -> 0 | X36: =IFERROR(VLOOKUP($W36,'Ref tables'!$C$18:$D$31,2,0),0) -> 0 | Y36: =V36*X36 -> 0
D37: =IFERROR(VLOOKUP($C37,'Ref tables'!$C$18:$D$31,2,0),0) -> 0 | E37: =B37*D37 -> 0 | I37: =IFERROR(VLOOKUP($H37,'Ref tables'!$C$18:$D$31,2,0),0) -> 0 | J37: =G37*I37 -> 0 | N37: =IFERROR(VLOOKUP($M37,'Ref tables'!$C$18:$D$31,2,0),0) -> 0 | O37: =L37*N37 -> 0 | S37: =IFERROR(VLOOKUP($R37,'Ref tables'!$C$18:$D$31,2,0),0) -> 0 | T37: =Q37*S37 -> 0 | X37: =IFERROR(VLOOKUP($W37,'Ref tables'!$C$18:$D$31,2,0),0) -> 0 | Y37: =V37*X37 -> 0
D38: =IFERROR(VLOOKUP($C38,'Ref tables'!$C$18:$D$31,2,0),0) -> 0 | E38: =B38*D38 -> 0 | I38: =IFERROR(VLOOKUP($H38,'Ref tables'!$C$18:$D$31,2,0),0) -> 0 | J38: =G38*I38 -> 0 | N38: =IFERROR(VLOOKUP($M38,'Ref tables'!$C$18:$D$31,2,0),0) -> 0 | O38: =L38*N38 -> 0 | S38: =IFERROR(VLOOKUP($R38,'Ref tables'!$C$18:$D$31,2,0),0) -> 0 | T38: =Q38*S38 -> 0 | X38: =IFERROR(VLOOKUP($W38,'Ref tables'!$C$18:$D$31,2,0),0) -> 0 | Y38: =V38*X38 -> 0
... D49: =IFERROR(VLOOKUP($C49,'Ref tables'!$C$18:$D$31,2,0),0) -> 0 | E49: =B49*D49 -> 0 | I49: =IFERROR(VLOOKUP($H49,'Ref tables'!$C$18:$D$31,2,0),0) -> 0 | J49: =G49*I49 -> 0 | N49: =IFERROR(VLOOKUP($M49,'Ref tables'!$C$18:$D$31,2,0),0) -> 0 | O49: =L49*N49 -> 0 | S49: =IFERROR(VLOOKUP($R49,'Ref tables'!$C$18:$D$31,2,0),0) -> 0 | T49: =Q49*S49 -> 0 | X49: =IFERROR(VLOOKUP($W49,'Ref tables'!$C$18:$D$31,2,0),0) -> 0 | Y49: =V49*X49 -> 0

Sheet Ref tables
C3: Dầu - Phát điện | D3: Nhiệt Trị | E3: Hệ số CO2 | G3: Than | H3: Nhiệt Trị | I3: Hệ số CO2 | L3: Sinh khối | M3: Nhiệt Trị | N3: Hệ số CO2 | P3: Xăng cho Oto | Q3: Nhiệt Trị | R3: Hệ số CO2 | T3: GAS | U3: Nhiệt Trị | V3: Hệ số CO2
C4: Dầu DO -Lít | D4: 36.8 | E4: 2.7 | G4: Than cốc | H4: 31.402 | I4: 1.83 | L4: Củi | M4: 16.1 | N4: 0 | P4: A92 | Q4: 36.8 | R4: 73.3 | T4: Liquefied Natural Gas (LNG) | U4: 46 | V4: 2.88
C5: Dầu FO-Lít | D5: 39.4 | E5: 3.046 | G5: Than antraxit cám loại 1,2 | H5: 29.309 | I5: 1.83 | L5: Trấu nén | M5: 16.2 | N5: 0 | P5: A95 | Q5: 36.8 | R5: 74.1 | T5: Liquefied Petroleum Gases (LPG) | U5: 37 | V5: 2.111
G6: Than antraxit cám loại 3,4 | H6: 25.122 | I6: 1.83 | P6: E5 | Q6: 36.8 | R6: 2.9 | T6: CNG | U6: 46 | V6: 2.88
G7: Than antraxit cám loại 5,6 | H7: 20.935 | I7: 1.83
G8: Than sub-bitum | H8: 25.122 | I8: 2.4
G9: Than Cục 5A | H9: 32.8 | I9: 3.221
F16: Máy lạnh
C17: Loại Rác thải | D17: Hệ số phát thải Emission factor (Kg CO2/Kg) | F17: Refrigerant Used (Compulsory) Loại gas (bắt buộc phải có) | G17: hệ số phát thải
C18: Batteries -Pin | D18: 854344 | F18: Carbon dioxide | G18: 1
C19: Clothing - Vải | D19: 4449759 | F19: Methane | G19: 25
C20: Commercial and industrial waste - Rác Thương mại và công nghiệp | D20: 4581763 | F20: Nitrous oxide | G20: 298
C21: Concrete - Bê tông | D21: 12489 | F21: HFC-23 | G21: 14.8
C22: Glass - kính | D22: 89344 | F22: HFC-32 | G22: 675
C23: Household residual waste - rác sinh hoạt | D23: 4373719 | F23: HFC-41 | G23: 92
C24: Rác thải kim loại | D24: 89344 | F24: HFC-125 | G24: 3.5
C25: Organic: food and drink waste -Rác thải hữu cơ thực phẩm và đồ uống | D25: 6269073 | F25: HFC-134 | G25: 1.1
C26: Giấy | D26: 10418361 | F26: HFC-134a | G26: 1.43
C27: Nhựa PET | D27: 89344 | F27: HFC-143 | G27: 353
C28: Nhựa PVC | D28: 89344 | F28: HFC-143a | G28: 4.47
C29: Nhựa PS | D29: 89344 | F29: HFC-152a | G29: 124
... C31: Cao Su | D31: 89344 | F31: HFC-236fa | G31: 9.81
F32: HFC-245fa | G32: 1.03
F33: HFC-43-I0mee | G33: 1.64
F34: Perfluoromethane (PFC-14) | G34: 7.39
F35: Perfluoroethane (PFC-116) | G35: 12.2
F36: Perfluoropropane (PFC-218) | G36: 8.83
F37: Perfluorocyclobutane (PFC-318) | G37: 10.3
F38: Perfluorobutane (PFC-3-1-10) | G38: 8.86
F39: Perfluoropentane (PFC-4-1-12) | G39: 9.16
F40: Perfluorohexane (PFC-5-1-14) | G40: 9.3
F41: Sulphur hexafluoride (SF6) | G41: 22.8
F42: HFC-152 | G42: 53
F43: HFC-161 | G43: 12
... F50: R407C | G50: 1.774

Sheet HVAC
A1: Vui lòng không thay đổi template khi nhập liệu, xin cảm ơn.
A2: Machine name (Compulsory) Tên Thiết bị máy móc (bắt buộc phải có) | B2: Model | C2: Motor capacity (Compulsory) Công suất (kW) (bắt buộc phải có) | D2: Quantity (Compulsory) Số lượng (bắt buộc phải có) | E2: Refrigerant Used (Compulsory) Loại gas (bắt buộc phải có) | F2: Hệ số phát thải | G2: Lượng gas ban đầu | H2: Tàn suất nạp gas thêm | I2: Tổng lượng gas nạp thêm | J2: kg CO2e | K2: Operation time /day (hours/day) (Compulsory) Thời gian vận hành/ngày (giờ/ngày) (bắt buộc phải có)
L3: Vui lòng nhập liệu bắt đầu tại dòng này. Xin cảm ơn

Sheet Lighting
A1: Vui lòng không thay đổi template khi nhập liệu, xin cảm ơn.
A2: Tên đèn | B2: Số lượng (Bộ) | C2: Công suất (W) | D2: Thời gian sử dụng (giờ/ngày) | E2: Khu vực sử dụng
F3: Vui lòng nhập liệu bắt đầu tại dòng này. Xin cảm ơn

Sheet Boiler & Thermopac
A1: Vui lòng không thay đổi template khi nhập liệu, xin cảm ơn.
A2: Tên Lò | B2: Model | C2: Số lượng | D2: Công suất thiết kế(tấn/h) | E2: Loại nhiên liệu(dầu) | F2: Thời gian hoạt động(giờ/năm) | G2: Tiêu thụ nhiên liệu trung bình trong ngày | H2: Nhiệt độ khói thải trung bình (oC) | I2: Nhiệt độ thân lò(oC) | J2: Hiệu suất lò (%) | K2: Nhà chế tạo | L2: Năm chế tạo
M3: Vui lòng nhập liệu bắt đầu tại dòng này. Xin cảm ơn

Sheet Air compressor
A1: Vui lòng không thay đổi template khi nhập liệu, xin cảm ơn.
A2: Tên máy | B2: Capacity Công suất (kW) | C2: Model | D2: Áp suất cài đặt (Bar) | E2: Hiệu suất (m3/p) | F2: Hiệu suất (kWh/m3) | G2: Số giờ hoạt động/ngày | H2: Khu vực sử dụng | I2: Đồng hồ điên | J2: Đồng hồ lưu lượng khí nén
K3: Vui lòng nhập liệu bắt đầu tại dòng này. Xin cảm ơn

Sheet Bơm quạt
A1: Vui lòng không thay đổi template khi nhập liệu, xin cảm ơn.
A2: Machine name (Compulsory) Tên Thiết bị máy móc (bắt buộc phải có) | B2: Model | C2: Motor capacity (Compulsory) Công suất (kW) (bắt buộc phải có) | D2: Speed (rpm) Tốc độ (vòng/phút) | E2: Quantity (Compulsory) Số lượng (bắt buộc phải có) | F2: Cột áp thiết kế (m) | G2: Lưu lượng thiết kế (m3/h) | H2: Motor Efficiency of design (%)_ Hiệu suất thiết kế của động cơ (%) | I2: Operation time /day (hours/day) (Compulsory) Thời gian vận hành/ngày (giờ/ngày) (bắt buộc phải có)
J3: Vui lòng nhập liệu bắt đầu tại dòng này. Xin cảm ơn
