Workbook

Sheet Tiêu thụ điện
B1: kWh | F1: VND | J1: Đơn giá | K1: Productivity | L1: MJ | M1: kg CO2 | N1: kWh/pr | O1: MJ/pr | P1: kgCO2/pr | Q1: VND/kWh
B2: BT | C2: CD | D2: TD | E2: Tổng cộng | F2: BT | G2: CD | H2: TD | I2: Tổng cộng | K2: pair
A3: 44197 | B3: 129500 | C3: 52500 | D3: 3500 | E3: =SUM(B3:D3) -> 185500 | F3: 201372500 | G3: 150727500 | H3: 3524500 | I3: =SUM(F3:H3) -> 355624500 | J3: =I3/E3 -> 1917.1132 | K3: 0 | L3: =E3*3.6 -> 667800 | M3: =E3*0.6766 -> 125509.3 | Q3: =I3/E3 -> 1917.1132
A4: 44228 | B4: 94500 | C4: 31500 | D4: 3500 | E4: =SUM(B4:D4) -> 129500 | F4: 146947500 | G4: 90436500 | H4: 3524500 | I4: =SUM(F4:H4) -> 240908500 | J4: =I4/E4 -> 1860.2973 | K4: 0 | L4: =E4*3.6 -> 466200 | M4: =E4*0.6766 -> 87619.7 | Q4: =I4/E4 -> 1860.2973
A5: 44256 | B5: 140000 | C5: 59500 | D5: 7000 | E5: =SUM(B5:D5) -> 206500 | F5: 217700000 | G5: 170824500 | H5: 7049000 | I5: =SUM(F5:H5) -> 395573500 | J5: =I5/E5 -> 1915.6102 | K5: 0 | L5: =E5*3.6 -> 743400 | M5: =E5*0.6766 -> 139717.9 | Q5: =I5/E5 -> 1915.6102
A6: 44287 | B6: 178500 | C6: 84000 | D6: 7000 | E6: =SUM(B6:D6) -> 269500 | F6: 277567500 | G6: 241164000 | H6: 7049000 | I6: =SUM(F6:H6) -> 525780500 | J6: =I6/E6 -> 1950.9481 | K6: 0 | L6: =E6*3.6 -> 970200 | M6: =E6*0.6766 -> 182343.7 | Q6: =I6/E6 -> 1950.9481
A7: 44317 | B7: 164500 | C7: 84000 | D7: 7000 | E7: =SUM(B7:D7) -> 255500 | F7: 255797500 | G7: 241164000 | H7: 7049000 | I7: =SUM(F7:H7) -> 504010500 | J7: =I7/E7 -> 1972.6438 | K7: 0 | L7: =E7*3.6 -> 919800 | M7: =E7*0.6766 -> 172871.3 | Q7: =I7/E7 -> 1972.6438
A8: 44348 | B8: 245000 | C8: 129500 | D8: 14000 | E8: =SUM(B8:D8) -> 388500 | F8: 380975000 | G8: 371794500 | H8: 14098000 | I8: =SUM(F8:H8) -> 766867500 | J8: =I8/E8 -> 1973.9189 | K8: 0 | L8: =E8*3.6 -> 1398600 | M8: =E8*0.6766 -> 262859.1 | Q8: =I8/E8 -> 1973.9189
A9: 44378 | B9: 280000 | C9: 140000 | D9: 10500 | E9: =SUM(B9:D9) -> 430500 | F9: 435400000 | G9: 401940000 | H9: 10573500 | I9: =SUM(F9:H9) -> 847913500 | J9: =I9/E9 -> 1969.6016 | K9: 0 | L9: =E9*3.6 -> 1549800 | M9: =E9*0.6766 -> 291276.3 | Q9: =I9/E9 -> 1969.6016
A10: 44409 | B10: 301000 | C10: 157500 | D10: 10500 | E10: =SUM(B10:D10) -> 469000 | F10: 468055000 | G10: 452182500 | H10: 10573500 | I10: =SUM(F10:H10) -> 930811000 | J10: =I10/E10 -> 1984.6716 | K10: 0 | L10: =E10*3.6 -> 1688400 | M10: =E10*0.6766 -> 317325.4 | Q10: =I10/E10 -> 1984.6716
A11: 44440 | B11: 262500 | C11: 110285 | D11: 12530 | E11: =SUM(B11:D11) -> 385315 | F11: 408187500 | G11: 316628235 | H11: 12617710 | I11: =SUM(F11:H11) -> 737433445 | J11: =I11/E11 -> 1913.8457 | K11: 0 | L11: =E11*3.6 -> 1387134 | M11: =E11*0.6766 -> 260704.13 | Q11: =I11/E11 -> 1913.8457
A12: 44470 | B12: 287735 | C12: 112105 | D12: 9415 | E12: =SUM(B12:D12) -> 409255 | F12: 447427925 | G12: 321853455 | H12: 9480905 | I12: =SUM(F12:H12) -> 778762285 | J12: =I12/E12 -> 1902.8779 | K12: 0 | L12: =E12*3.6 -> 1473318 | M12: =E12*0.6766 -> 276901.93 | Q12: =I12/E12 -> 1902.8779
A13: 44501 | B13: 246271 | C13: 101283 | D13: 8894 | E13: =SUM(B13:D13) -> 356448 | F13: 382951405 | G13: 290783493 | H13: 8956258 | I13: =SUM(F13:H13) -> 682691156 | J13: =I13/E13 -> 1915.2616 | K13: 23289 | L13: =E13*3.6 -> 1283212.8 | M13: =E13*0.6766 -> 241172.72 | N13: =E13/K13 -> 15.305423 | O13: =N13*3.6 -> 55.099523 | P13: =N13*0.6766 -> 10.355649 | Q13: =I13/E13 -> 1915.2616
A14: 44531 | B14: 144995 | C14: 57827 | D14: 4162 | E14: =SUM(B14:D14) -> 206984 | F14: 225467225 | G14: 166021317 | H14: 4191134 | I14: =SUM(F14:H14) -> 395679676 | J14: =I14/E14 -> 1911.6438 | K14: 27099 | L14: =E14*3.6 -> 745142.4 | M14: =E14*0.6766 -> 140045.37 | N14: =E14/K14 -> 7.6380678 | O14: =N14*3.6 -> 27.497044 | P14: =N14*0.6766 -> 5.1679167 | Q14: =I14/E14 -> 1911.6438
A15: Tổng cộng 2021 | B15: =SUBTOTAL(9,B3:B14) -> 2474501 | C15: =SUBTOTAL(9,C3:C14) -> 1120000 | D15: =SUBTOTAL(9,D3:D14) -> 98001 | E15: =SUBTOTAL(9,E3:E14) -> 3692502 | F15: =SUBTOTAL(9,F3:F14) -> 3847849055 | G15: =SUBTOTAL(9,G3:G14) -> 3215520000 | H15: =SUBTOTAL(9,H3:H14) -> 98687007 | I15: =SUBTOTAL(9,I3:I14) -> 7162056062 | J15: =I15/E15 -> 1939.6214 | K15: =SUBTOTAL(9,K3:K14) -> 50388 | L15: =SUBTOTAL(9,L3:L14) -> 13293007 | M15: =SUBTOTAL(9,M3:M14) -> 2498346.9 | Q15: =I15/E15 -> 1939.6214
A16: 44562 | B16: 126518 | C16: 14616 | D16: 304028 | E16: =SUM(B16:D16) -> 445162 | F16: 363233178 | G16: 14718312 | H16: 472763540 | I16: =SUM(F16:H16) -> 850715030 | J16: =I16/E16 -> 1911.0235 | K16: 88188 | L16: =E16*3.6 -> 1602583.2 | M16: =E16*0.6766 -> 301196.61 | N16: =E16/K16 -> 5.047875 | O16: =N16*3.6 -> 18.17235 | P16: =N16*0.6766 -> 3.4153922 | Q16: =I16/E16 -> 1911.0235
A17: 44593 | B17: 123943 | C17: 12055 | D17: 295313 | E17: =SUM(B17:D17) -> 431311 | F17: 355840353 | G17: 12139385 | H17: 459211715 | I17: =SUM(F17:H17) -> 827191453 | J17: =I17/E17 -> 1917.8538 | K17: 93437 | L17: =E17*3.6 -> 1552719.6 | M17: =E17*0.6766 -> 291825.02 | N17: =E17/K17 -> 4.6160622 | O17: =N17*3.6 -> 16.617824 | P17: =N17*0.6766 -> 3.1232277 | Q17: =I17/E17 -> 1917.8538
A18: 44621 | B18: 168013 | C18: 20301 | D18: 365845 | E18: =SUM(B18:D18) -> 554159 | F18: 482339484 | G18: 20443107 | H18: 568888975 | I18: =SUM(F18:H18) -> 1071671566 | J18: =I18/E18 -> 1933.8702 | K18: 187118 | L18: =E18*3.6 -> 1994972.4 | M18: =E18*0.6766 -> 374943.98 | N18: =E18/K18 -> 2.9615483 | O18: =N18*3.6 -> 10.661574 | P18: =N18*0.6766 -> 2.0037836 | Q18: =I18/E18 -> 1933.8702
A19: 44652 | B19: 226916 | C19: 47322 | D19: 519478 | E19: =SUM(B19:D19) -> 793716 | F19: 651475836 | G19: 48314853 | H19: 807788290 | I19: =SUM(F19:H19) -> 1507578979 | J19: =I19/E19 -> 1899.3935 | K19: 308466 | L19: =E19*3.6 -> 2857377.6 | M19: =E19*0.6766 -> 537028.25 | N19: =E19/K19 -> 2.5731069 | O19: =N19*3.6 -> 9.2631849 | P19: =N19*0.6766 -> 1.7409641 | Q19: =I19/E19 -> 1899.3935
A20: 44682 | B20: 202105 | C20: 51888 | D20: 576829 | E20: =SUM(B20:D20) -> 830822 | F20: 580243455 | G20: 52251216 | H20: 896969095 | I20: =SUM(F20:H20) -> 1529463766 | J20: =I20/E20 -> 1840.9043 | K20: 351801 | L20: =E20*3.6 -> 2990959.2 | M20: =E20*0.6766 -> 562134.17 | N20: =E20/K20 -> 2.3616249 | O20: =N20*3.6 -> 8.5018496 | P20: =N20*0.6766 -> 1.5978754 | Q20: =I20/E20 -> 1840.9043
A21: 44713 | B21: 311171 | C21: 86037 | D21: 799169 | E21: =SUM(B21:D21) -> 1196377 | F21: 893371931 | G21: 86639259 | H21: 1242707805 | I21: =SUM(F21:H21) -> 2222718995 | J21: =I21/E21 -> 1857.8751 | K21: 453767 | L21: =E21*3.6 -> 4306957.2 | M21: =E21*0.6766 -> 809468.68 | N21: =E21/K21 -> 2.6365447 | O21: =N21*3.6 -> 9.4915611 | P21: =N21*0.6766 -> 1.7838862 | Q21: =I21/E21 -> 1857.8751
A22: 44743 | B22: 336091 | C22: 101731 | D22: 838530 | E22: =SUM(B22:D22) -> 1276352 | F22: 964917261 | G22: 102443117 | H22: 1303914150 | I22: =SUM(F22:H22) -> 2371274528 | J22: =I22/E22 -> 1857.8531 | K22: 550573 | L22: =E22*3.6 -> 4594867.2 | M22: =E22*0.6766 -> 863579.76 | N22: =E22/K22 -> 2.3182248 | O22: =N22*3.6 -> 8.3456094 | P22: =N22*0.6766 -> 1.5685109 | Q22: =I22/E22 -> 1857.8531
A23: 44774 | B23: 334430 | C23: 120806 | D23: 909496 | E23: =SUM(B23:D23) -> 1364732 | F23: 961440480 | G23: 121651642 | H23: 1414266280 | I23: =SUM(F23:H23) -> 2497358402 | J23: =I23/E23 -> 1829.9259 | K23: 700152 | L23: =E23*3.6 -> 4913035.2 | M23: =E23*0.6766 -> 923377.67 | N23: =E23/K23 -> 1.9491939 | O23: =N23*3.6 -> 7.017098 | P23: =N23*0.6766 -> 1.3188246 | Q23: =I23/E23 -> 1829.9259
A24: 44805 | B24: 313929 | C24: 153601 | D24: 900158 | E24: =SUM(B24:D24) -> 1367688 | F24: 901290159 | G24: 154676207 | H24: 1399745690 | I24: =SUM(F24:H24) -> 2455712056 | J24: =I24/E24 -> 1795.5207 | K24: 567211 | L24: =E24*3.6 -> 4923676.8 | M24: =E24*0.6766 -> 925377.7 | N24: =E24/K24 -> 2.4112508 | O24: =N24*3.6 -> 8.680503 | P24: =N24*0.6766 -> 1.6314523 | Q24: =I24/E24 -> 1795.5207
A25: 44835 | B25: 528150 | C25: 170660 | D25: 898660 | E25: =SUM(B25:D25) -> 1597470 | F25: 1158432450 | G25: 171854620 | H25: 1516158980 | I25: =SUM(F25:H25) -> 2846446050 | J25: =I25/E25 -> 1781.8463 | K25: 701525 | L25: =E25*3.6 -> 5750892 | M25: =E25*0.6766 -> 1080848.2 | N25: =E25/K25 -> 2.2771391 | O25: =N25*3.6 -> 8.1977007 | P25: =N25*0.6766 -> 1.5407123 | Q25: =I25/E25 -> 1781.8463
A26: 44866 | B26: 251510 | C26: 110530 | D26: 867650 | E26: =SUM(B26:D26) -> 1229690 | F26: 722085210 | G26: 111303710 | H26: 1349195750 | I26: =SUM(F26:H26) -> 2182584670 | J26: =I26/E26 -> 1774.9064 | K26: 660274 | L26: =E26*3.6 -> 4426884 | M26: =E26*0.6766 -> 832008.25 | N26: =E26/K26 -> 1.8623935 | O26: =N26*3.6 -> 6.7046166 | P26: =N26*0.6766 -> 1.2600954 | Q26: =I26/E26 -> 1774.9064
A27: 44896 | B27: 173530 | C27: 110810 | D27: 769440 | E27: =SUM(B27:D27) -> 1053780 | F27: 498204630 | G27: 111585670 | H27: 1196479200 | I27: =SUM(F27:H27) -> 1806269500 | J27: =I27/E27 -> 1714.086 | K27: 657397 | L27: =E27*3.6 -> 3793608 | M27: =E27*0.6766 -> 712987.55 | N27: =E27/K27 -> 1.6029583 | O27: =N27*3.6 -> 5.77065 | P27: =N27*0.6766 -> 1.0845616 | Q27: =I27/E27 -> 1714.086
A28: Tổng cộng 2022 | B28: =SUBTOTAL(9,B16:B27) -> 3096306 | C28: =SUBTOTAL(9,C16:C27) -> 1000357 | D28: =SUBTOTAL(9,D16:D27) -> 8044596 | E28: =SUBTOTAL(9,E16:E27) -> 12141259 | F28: =SUBTOTAL(9,F16:F27) -> 8532874427 | G28: =SUBTOTAL(9,G16:G27) -> 1008021098 | H28: =SUBTOTAL(9,H16:H27) -> 12628089470 | I28: =SUBTOTAL(9,I16:I27) -> 22168984995 | J28: =I28/E28 -> 1825.9214 | K28: =SUBTOTAL(9,K16:K27) -> 5319909 | L28: =SUBTOTAL(9,L16:L27) -> 43708532 | M28: =SUBTOTAL(9,M16:M27) -> 8214775.8
A29: 44927 | B29: 425320 | C29: 103880 | D29: 57470 | E29: =SUM(B29:D29) -> 586670 | F29: 661372600 | G29: 298239480 | H29: 57872290 | I29: =SUM(F29:H29) -> 1017484370 | J29: =I29/E29 -> 1734.3385 | K29: 442109 | L29: =E29*3.6 -> 2112012 | M29: =E29*0.6766 -> 396940.92 | N29: =E29/K29 -> 1.3269805 | O29: =N29*3.6 -> 4.7771296 | P29: =N29*0.6766 -> 0.89783497 | Q29: =I29/E29 -> 1734.3385
A30: 44958 | B30: 658700 | C30: 164710 | D30: 46270 | E30: =SUM(B30:D30) -> 869680 | F30: 1024278500 | G30: 472882410 | H30: 46593890 | I30: =SUM(F30:H30) -> 1543754800 | J30: =I30/E30 -> 1775.0837 | K30: 621191 | L30: =E30*3.6 -> 3130848 | M30: =E30*0.6766 -> 588425.49 | N30: =E30/K30 -> 1.4000203 | O30: =N30*3.6 -> 5.040073 | P30: =N30*0.6766 -> 0.94725372 | Q30: =I30/E30 -> 1775.0837
A31: 44986 | B31: 838460 | C31: 232120 | D31: 62062 | E31: =SUM(B31:D31) -> 1132642 | F31: 1303805300 | G31: 666416520 | H31: 62454140 | I31: =SUM(F31:H31) -> 2032675960 | J31: =I31/E31 -> 1794.6323 | K31: 780207 | L31: =E31*3.6 -> 4077511.2 | M31: =E31*0.6766 -> 766345.58 | N31: =E31/K31 -> 1.4517199 | O31: =N31*3.6 -> 5.2261915 | P31: =N31*0.6766 -> 0.98223366 | Q31: =I31/E31 -> 1794.6323
A32: 45017 | B32: 885070 | C32: 268100 | D32: 75600 | E32: =SUM(B32:D32) -> 1228770 | F32: 1371618850 | G32: 769715100 | H32: 76129200 | I32: =SUM(F32:H32) -> 2217463150 | J32: =I32/E32 -> 1804.6202 | K32: 800208 | L32: =E32*3.6 -> 4423572 | M32: =E32*0.6766 -> 831385.78 | N32: =E32/K32 -> 1.5355633 | O32: =N32*3.6 -> 5.5280277 | P32: =N32*0.6766 -> 1.0389621 | Q32: =I32/E32 -> 1804.6202
A33: 45047 | B33: 835590 | C33: 266980 | D33: 57190 | E33: =SUM(B33:D33) -> 1159760 | F33: 1337933380 | G33: 788687900 | H33: 59142230 | I33: =SUM(F33:H33) -> 2185763510 | J33: =I33/E33 -> 1884.6688 | K33: 860646 | L33: =E33*3.6 -> 4175136 | M33: =E33*0.6766 -> 784693.62 | N33: =E33/K33 -> 1.3475459 | O33: =N33*3.6 -> 4.8511653 | P33: =N33*0.6766 -> 0.91174956 | Q33: =I33/E33 -> 1884.6688
A34: 45078 | B34: 735420 | C34: 198030 | D34: 54390 | E34: =SUM(B34:D34) -> 987840 | F34: 1179613680 | G34: 585970770 | H34: 56402430 | I34: =SUM(F34:H34) -> 1821986880 | J34: =I34/E34 -> 1844.415 | K34: 800166 | L34: =E34*3.6 -> 3556224 | M34: =E34*0.6766 -> 668372.54 | N34: =E34/K34 -> 1.2345438 | O34: =N34*3.6 -> 4.4443578 | P34: =N34*0.6766 -> 0.83529236 | Q34: =I34/E34 -> 1844.415
A35: 45108 | B35: 790090 | C35: 245420 | D35: 64120 | E35: =SUM(B35:D35) -> 1099630 | F35: 1378798400 | G35: 726197780 | H35: 66492440 | I35: =SUM(F35:H35) -> 2171488620 | J35: =I35/E35 -> 1974.7448 | K35: 766156 | L35: =E35*3.6 -> 3958668 | M35: =E35*0.6766 -> 744009.66 | N35: =E35/K35 -> 1.435256 | O35: =N35*3.6 -> 5.1669216 | P35: =N35*0.6766 -> 0.97109421 | Q35: =I35/E35 -> 1974.7448
A36: 45139 | B36: 999390 | C36: 301910 | D36: 109760 | E36: =SUM(B36:D36) -> 1411060 | F36: 1603021560 | G36: 893351690 | H36: 113821120 | I36: =SUM(F36:H36) -> 2610194370 | J36: =I36/E36 -> 1849.811 | K36: 840154 | L36: =E36*3.6 -> 5079816 | M36: =E36*0.6766 -> 954723.2 | N36: =E36/K36 -> 1.6795254 | O36: =N36*3.6 -> 6.0462915 | P36: =N36*0.6766 -> 1.1363669 | Q36: =I36/E36 -> 1849.811
A37: 45170 | B37: 806036 | C37: 292310 | D37: 206080 | E37: =SUM(B37:D37) -> 1304426 | F37: 1468510120 | G37: 866010530 | H37: 101480820 | I37: =SUM(F37:H37) -> 2436001470 | J37: =I37/E37 -> 1867.4892 | K37: 740042 | L37: =E37*3.6 -> 4695933.6 | M37: =E37*0.6766 -> 882574.63 | N37: =E37/K37 -> 1.7626378 | O37: =N37*3.6 -> 6.3454961 | P37: =N37*0.6766 -> 1.1926007 | Q37: =I37/E37 -> 1867.4892
A38: 45200 | B38: 837193 | C38: 334250 | D38: 118370 | E38: =SUM(B38:D38) -> 1289813 | F38: 1628733680 | G38: 989045750 | H38: 122749690 | I38: =SUM(F38:H38) -> 2740529120 | J38: =I38/E38 -> 2124.7492 | K38: 860065 | L38: =E38*3.6 -> 4643326.8 | M38: =E38*0.6766 -> 872687.48 | N38: =E38/K38 -> 1.4996692 | O38: =N38*3.6 -> 5.3988092 | P38: =N38*0.6766 -> 1.0146762 | Q38: =I38/E38 -> 2124.7492
A39: 45231 | B39: 874790 | C39: 394100 | D39: 122150 | E39: =SUM(B39:D39) -> 1391040 | F39: 1595184850 | G39: 958436640 | H39: 116810050 | I39: =SUM(F39:H39) -> 2670431540 | J39: =I39/E39 -> 1919.7374 | K39: 901232 | L39: =E39*3.6 -> 5007744 | M39: =E39*0.6766 -> 941177.66 | N39: =E39/K39 -> 1.5434871 | O39: =N39*3.6 -> 5.5565537 | P39: =N39*0.6766 -> 1.0443234 | Q39: =I39/E39 -> 1919.7374
A40: 45261 | B40: 979020 | C40: 302120 | D40: 93380 | E40: =SUM(B40:D40) -> 1374520 | F40: 1633984380 | G40: 934457160 | H40: 101223920 | I40: =SUM(F40:H40) -> 2669665460 | J40: =I40/E40 -> 1942.2529 | K40: 1020188 | L40: =E40*3.6 -> 4948272 | M40: =E40*0.6766 -> 930000.23 | N40: =E40/K40 -> 1.3473203 | O40: =N40*3.6 -> 4.8503531 | P40: =N40*0.6766 -> 0.91159691 | Q40: =I40/E40 -> 1942.2529
...

Sheet Tiêu thụ xăng
B1: Tiêu thụ lít | C1: Chi phí VND | D1: MJ | E1: kg CO2 | F1: Productivity | G1: STH
A2: 44197 | D2: =0.82*47.69*B2 -> 0 | E2: =2.7823*B2 -> 0 | F2: 0
A3: 44228 | B3: 2530 | C3: 43007371 | D3: =0.82*47.69*B3 -> 98937.674 | E3: =2.7823*B3 -> 7039.219 | F3: 0
A4: 44256 | B4: 2230 | C4: 32183500 | D4: =0.82*47.69*B4 -> 87205.934 | E4: =2.7823*B4 -> 6204.529 | F4: 0
A5: 44287 | B5: 2705 | C5: 39140600 | D5: =0.82*47.69*B5 -> 105781.19 | E5: =2.7823*B5 -> 7526.1215 | F5: 0
A6: 44317 | B6: 1785 | C6: 32097100 | D6: =0.82*47.69*B6 -> 69803.853 | E6: =2.7823*B6 -> 4966.4055 | F6: 0
A7: 44348 | B7: 2351 | C7: 44872431 | D7: =0.82*47.69*B7 -> 91937.736 | E7: =2.7823*B7 -> 6541.1873 | F7: 0
A8: 44378 | B8: 2019 | C8: 41975651 | D8: =0.82*47.69*B8 -> 78954.61 | E8: =2.7823*B8 -> 5617.4637 | F8: 0
A9: 44409 | B9: 1455 | C9: 27838500 | D9: =0.82*47.69*B9 -> 56898.939 | E9: =2.7823*B9 -> 4048.2465 | F9: 0
A10: 44440 | B10: 1065 | C10: 23115450 | D10: =0.82*47.69*B10 -> 41647.677 | E10: =2.7823*B10 -> 2963.1495 | F10: 0
A11: 44470 | B11: 755 | C11: 28177334 | D11: =0.82*47.69*B11 -> 29524.879 | E11: =2.7823*B11 -> 2100.6365 | F11: 0
A12: 44501 | B12: 1500 | C12: 37692000 | D12: =0.82*47.69*B12 -> 58658.7 | E12: =2.7823*B12 -> 4173.45 | F12: 23289
A13: 44531 | B13: 1425 | C13: 30959319 | D13: =0.82*47.69*B13 -> 55725.765 | E13: =2.7823*B13 -> 3964.7775 | F13: 27099
A14: Tổng cộng 2021 | B14: =SUBTOTAL(9,B2:B13) -> 19820 | C14: =SUBTOTAL(9,C2:C13) -> 381059256 | D14: =SUBTOTAL(9,D2:D13) -> 775076.96 | E14: =SUBTOTAL(9,E2:E13) -> 55145.186 | F14: =SUBTOTAL(9,F2:F13) -> 50388
A15: 44562 | B15: 1555 | C15: 37401850 | D15: =0.82*47.69*B15 -> 60809.519 | E15: =2.7823*B15 -> 4326.4765 | F15: 88188
A16: 44593 | B16: 1475 | C16: 37736600 | D16: =0.82*47.69*B16 -> 57681.055 | E16: =2.7823*B16 -> 4103.8925 | F16: 93437
A17: 44621 | B17: 1681 | C17: 48466380 | D17: =0.82*47.69*B17 -> 65736.85 | E17: =2.7823*B17 -> 4677.0463 | F17: 187118
A18: 44652 | B18: 3107 | C18: 87871630 | D18: =0.82*47.69*B18 -> 121501.72 | E18: =2.7823*B18 -> 8644.6061 | F18: 308466
A19: 44682 | B19: 4289 | C19: 128035910 | D19: =0.82*47.69*B19 -> 167724.78 | E19: =2.7823*B19 -> 11933.285 | F19: 351801
A20: 44713 | B20: 5377 | C20: 174510950 | D20: =0.82*47.69*B20 -> 210271.89 | E20: =2.7823*B20 -> 14960.427 | F20: 453767
A21: 44743 | B21: 4690 | C21: 145391240 | D21: =0.82*47.69*B21 -> 183406.2 | E21: =2.7823*B21 -> 13048.987 | F21: 550573
A22: 44774 | B22: 6315 | C22: 162969930 | D22: =0.82*47.69*B22 -> 246953.13 | E22: =2.7823*B22 -> 17570.225 | F22: 700152
A23: 44805 | B23: 5294 | C23: 128071900 | D23: =0.82*47.69*B23 -> 207026.11 | E23: =2.7823*B23 -> 14729.496 | F23: 567211
A24: 44835 | B24: 4423 | C24: 99890860 | D24: =0.82*47.69*B24 -> 172964.95 | E24: =2.7823*B24 -> 12306.113 | F24: 701525
A25: 44866 | B25: 3680 | C25: 85628820 | D25: =0.82*47.69*B25 -> 143909.34 | E25: =2.7823*B25 -> 10238.864 | F25: 660274
A26: 44896 | B26: 5989 | C26: 137278860 | D26: =0.82*47.69*B26 -> 234204.64 | E26: =2.7823*B26 -> 16663.195 | F26: 657397
A27: Tổng cộng 2021 | B27: =SUBTOTAL(9,B15:B26) -> 47875 | C27: =SUBTOTAL(9,C15:C26) -> 1273254930 | D27: =SUBTOTAL(9,D15:D26) -> 1872190.2 | E27: =SUBTOTAL(9,E15:E26) -> 133202.61 | F27: =SUBTOTAL(9,F15:F26) -> 5319909
A28: 44927 | B28: 3005 | C28: 66743350 | D28: =0.82*47.69*B28 -> 117512.93 | E28: =2.7823*B28 -> 8360.8115 | F28: 442109
A29: 44958 | B29: 5524 | C29: 129692860 | D29: =0.82*47.69*B29 -> 216020.44 | E29: =2.7823*B29 -> 15369.425 | F29: 621191
A30: 44986 | B30: 5482 | C30: 131043790 | D30: =0.82*47.69*B30 -> 214378 | E30: =2.7823*B30 -> 15252.569 | F30: 780207
A31: 45017 | B31: 5271 | C31: 126110900 | D31: =0.82*47.69*B31 -> 206126.67 | E31: =2.7823*B31 -> 14665.503 | F31: 800208
A32: 45047 | B32: 5241 | C32: 119558890 | D32: =0.82*47.69*B32 -> 204953.5 | E32: =2.7823*B32 -> 14582.034 | F32: 860646
A33: 45078 | B33: 5428 | C33: 120989200 | D33: =0.82*47.69*B33 -> 212266.28 | E33: =2.7823*B33 -> 15102.324 | F33: 800166
A34: 45108 | B34: 4504.69 | C34: 99673480 | D34: =0.82*47.69*B34 -> 176159.51 | E34: =2.7823*B34 -> 12533.399 | F34: 766156
A35: 45139 | B35: 5599 | C35: 134956180 | D35: =0.82*47.69*B35 -> 218953.37 | E35: =2.7823*B35 -> 15578.098 | F35: 840154
A36: 45170 | B36: 6311 | C36: 159837320 | D36: =0.82*47.69*B36 -> 246796.7 | E36: =2.7823*B36 -> 17559.095 | F36: 740042
A37: 45200 | B37: 5250 | C37: 131214940 | D37: =0.82*47.69*B37 -> 205305.45 | E37: =2.7823*B37 -> 14607.075 | F37: 860065
A38: 45231 | B38: 5784 | C38: 139811800 | D38: =0.82*47.69*B38 -> 226187.95 | E38: =2.7823*B38 -> 16092.823 | F38: 901232
A39: 45261 | B39: 5686 | C39: 130606320 | D39: =0.82*47.69*B39 -> 222355.58 | E39: =2.7823*B39 -> 15820.158 | F39: 1020188
A40: Tổng cộng 2021 | B40: =SUBTOTAL(9,B28:B39) -> 63085.69 | C40: =SUBTOTAL(9,C28:C39) -> 1490239030 | D40: =SUBTOTAL(9,D28:D39) -> 2467016.4 | E40: =SUBTOTAL(9,E28:E39) -> 175523.32 | F40: =SUBTOTAL(9,F28:F39) -> 9432364
...

Sheet Tiêu thụ DO
B1: Tiêu thụ | F1: Chi phí | J1: MJ | K1: kg CO2
B2: Car | C2: Forklift | D2: Genetaror | E2: Tổng | F2: Car | G2: Forklift | H2: Genetaror | I2: Tổng
A3: 44197 | B3: 338 | E3: =SUM(B3:D3) -> 338 | F3: 5742000 | I3: =SUM(F3:H3) -> 5742000 | J3: =0.86*42.42*E3 -> 12330.646 | K3: =2.5423*E3 -> 859.2974
A4: 44228 | B4: 2193 | E4: =SUM(B4:D4) -> 2193 | F4: 37227769 | I4: =SUM(F4:H4) -> 37227769 | J4: =0.86*42.42*E4 -> 80003.272 | K4: =2.5423*E4 -> 5575.2639
A5: 44256 | B5: 1276 | E5: =SUM(B5:D5) -> 1276 | F5: 24289815 | I5: =SUM(F5:H5) -> 24289815 | J5: =0.86*42.42*E5 -> 46550.011 | K5: =2.5423*E5 -> 3243.9748
A6: 44287 | B6: 1592 | C6: 148 | D6: 852 | E6: =SUM(B6:D6) -> 2592 | F6: 30823450 | G6: 1953600 | H6: 11246400 | I6: =SUM(F6:H6) -> 44023450 | J6: =0.86*42.42*E6 -> 94559.27 | K6: =2.5423*E6 -> 6589.6416
A7: 44317 | B7: 2510 | C7: 144 | D7: 913 | E7: =SUM(B7:D7) -> 3567 | F7: 37188800 | G7: 1900800 | H7: 12051600 | I7: =SUM(F7:H7) -> 51141200 | J7: =0.86*42.42*E7 -> 130128.44 | K7: =2.5423*E7 -> 9068.3841
A8: 44348 | B8: 2210 | C8: 211 | D8: 941 | E8: =SUM(B8:D8) -> 3362 | F8: 33887800 | G8: 3019410 | H8: 14465710 | I8: =SUM(F8:H8) -> 51372920 | J8: =0.86*42.42*E8 -> 122649.79 | K8: =2.5423*E8 -> 8547.2126
A9: 44378 | B9: 2920 | C9: 233 | D9: 1160 | E9: =SUM(B9:D9) -> 4313 | F9: 48646400 | G9: 3480088 | H9: 17325760 | I9: =SUM(F9:H9) -> 69452248 | J9: =0.86*42.42*E9 -> 157343.42 | K9: =2.5423*E9 -> 10964.94
A10: 44409 | B10: 2980 | C10: 221 | D10: 1539 | E10: =SUM(B10:D10) -> 4740 | F10: 50705045 | G10: 3353233 | H10: 23351247 | I10: =SUM(F10:H10) -> 77409525 | J10: =0.86*42.42*E10 -> 172920.89 | K10: =2.5423*E10 -> 12050.502
A11: 44440 | B11: 800 | C11: 236 | D11: 1688 | E11: =SUM(B11:D11) -> 2724 | F11: 12916600 | G11: 3856240 | H11: 27581920 | I11: =SUM(F11:H11) -> 44354760 | J11: =0.86*42.42*E11 -> 99374.789 | K11: =2.5423*E11 -> 6925.2252
A12: 44470 | B12: 2480 | C12: 151 | D12: 834 | E12: =SUM(B12:D12) -> 3465 | F12: 43740000 | G12: 2321282 | H12: 12820854 | I12: =SUM(F12:H12) -> 58882136 | J12: =0.86*42.42*E12 -> 126407.36 | K12: =2.5423*E12 -> 8809.0695
A13: 44501 | B13: 1855 | C13: 320 | D13: 5335 | E13: =SUM(B13:D13) -> 7510 | F13: 35393400 | G13: 5550545.5 | H13: 92538000 | I13: =SUM(F13:H13) -> 1.3348195e+08 | J13: =0.86*42.42*E13 -> 273973.81 | K13: =2.5423*E13 -> 19092.673
A14: 44531 | B14: 3025 | C14: 342 | D14: 6437 | E14: =SUM(B14:D14) -> 9804 | F14: 50066181 | G14: 5826312 | H14: 109660732 | I14: =SUM(F14:H14) -> 165553225 | J14: =0.86*42.42*E14 -> 357661.68 | K14: =2.5423*E14 -> 24924.709
A15: Tổng cộng 2021 | B15: =SUBTOTAL(9,B3:B14) -> 24179 | C15: =SUBTOTAL(9,C3:C14) -> 2006 | D15: =SUBTOTAL(9,D3:D14) -> 19699 | E15: =SUBTOTAL(9,E3:E14) -> 45884 | F15: =SUBTOTAL(9,F3:F14) -> 410627260 | G15: =SUBTOTAL(9,G3:G14) -> 31261510 | H15: =SUBTOTAL(9,H3:H14) -> 321042223 | I15: =SUBTOTAL(9,I3:I14) -> 7.6293099e+08 | ... K15: =SUBTOTAL(9,K3:K14) -> 116650.89
A16: 44562 | B16: 3511 | C16: 366 | D16: 1150 | E16: =SUM(B16:D16) -> 5027 | F16: 65042140 | G16: 6235542 | H16: 19592550 | I16: =SUM(F16:H16) -> 90870232 | J16: =0.86*42.42*E16 -> 183390.99 | K16: =2.5423*E16 -> 12780.142
A17: 44593 | B17: 1891 | C17: 289 | D17: 756 | E17: =SUM(B17:D17) -> 2936 | F17: 37578230 | G17: 5852250 | H17: 15309000 | I17: =SUM(F17:H17) -> 58739480 | J17: =0.86*42.42*E17 -> 107108.8 | K17: =2.5423*E17 -> 7464.1928
A18: 44621 | B18: 3098 | C18: 237 | D18: 1335 | E18: =SUM(B18:D18) -> 4670 | F18: 74061960 | G18: 4879485 | H18: 26372925 | I18: =SUM(F18:H18) -> 105314370 | J18: =0.86*42.42*E18 -> 170367.2 | K18: =2.5423*E18 -> 11872.541
A19: 44652 | B19: 3611 | C19: 318 | D19: 1455 | E19: =SUM(B19:D19) -> 5384 | F19: 90935900 | G19: 6282090 | H19: 28743525 | I19: =SUM(F19:H19) -> 125961515 | J19: =0.86*42.42*E19 -> 196414.78 | K19: =2.5423*E19 -> 13687.743
A20: 44682 | B20: 3450 | C20: 415 | D20: 1536 | E20: =SUM(B20:D20) -> 5401 | F20: 91342940 | G20: 8198325 | H20: 30343680 | I20: =SUM(F20:H20) -> 129884945 | J20: =0.86*42.42*E20 -> 197034.96 | K20: =2.5423*E20 -> 13730.962
A21: 44713 | B21: 4268 | C21: 421 | D21: 853 | E21: =SUM(B21:D21) -> 5542 | F21: 120587150 | G21: 8316855 | H21: 16851015 | I21: =SUM(F21:H21) -> 145755020 | J21: =0.86*42.42*E21 -> 202178.81 | K21: =2.5423*E21 -> 14089.427
A22: 44743 | B22: 5550 | C22: 523 | D22: 1263 | E22: =SUM(B22:D22) -> 7336 | F22: 157119900 | G22: 10331627 | H22: 24949990 | I22: =SUM(F22:H22) -> 192401517 | J22: =0.86*42.42*E22 -> 267626.08 | K22: =2.5423*E22 -> 18650.313
A23: 44774 | B23: 7530 | C23: 336 | D23: 938 | E23: =SUM(B23:D23) -> 8804 | F23: 183615732 | G23: 7398109 | H23: 20653055 | I23: =SUM(F23:H23) -> 211666896 | J23: =0.86*42.42*E23 -> 321180.48 | K23: =2.5423*E23 -> 22382.409
A24: 44805 | B24: 8107 | C24: 435 | D24: 816 | E24: =SUM(B24:D24) -> 9358 | F24: 200017960 | G24: 9957830 | H24: 17966688 | I24: =SUM(F24:H24) -> 227942478 | J24: =0.86*42.42*E24 -> 341391.07 | K24: =2.5423*E24 -> 23790.843
A25: 44835 | B25: 8669 | C25: 652 | D25: 0 | E25: =SUM(B25:D25) -> 9321 | F25: 206275020 | G25: 14355855 | H25: 0 | I25: =SUM(F25:H25) -> 220630875 | J25: =0.86*42.42*E25 -> 340041.27 | K25: =2.5423*E25 -> 23696.778
A26: 44866 | B26: 5889 | C26: 611 | D26: 1400 | E26: =SUM(B26:D26) -> 7900 | F26: 149935830 | G26: 13654330 | H26: 30825456 | I26: =SUM(F26:H26) -> 194415616 | J26: =0.86*42.42*E26 -> 288201.48 | K26: =2.5423*E26 -> 20084.17
A27: 44896 | B27: 10922 | C27: 625 | D27: 965 | E27: =SUM(B27:D27) -> 12512 | F27: 225689840 | G27: 13761364 | H27: 21247546 | I27: =SUM(F27:H27) -> 260698750 | J27: =0.86*42.42*E27 -> 456452.77 | K27: =2.5423*E27 -> 31809.258
A28: Tổng cộng 2022 | B28: =SUBTOTAL(9,B16:B27) -> 66496 | C28: =SUBTOTAL(9,C16:C27) -> 5228 | D28: =SUBTOTAL(9,D16:D27) -> 12467 | E28: =SUBTOTAL(9,E16:E27) -> 84191 | F28: =SUBTOTAL(9,F16:F27) -> 1602202602 | G28: =SUBTOTAL(9,G16:G27) -> 109223662 | H28: =SUBTOTAL(9,H16:H27) -> 252855430 | I28: =SUBTOTAL(9,I16:I27) -> 1964281694 | ... K28: =SUBTOTAL(9,K16:K27) -> 214038.78
A29: 44927 | B29: 5418 | C29: 348 | D29: 755 | E29: =SUM(B29:D29) -> 6521 | F29: 120125780 | G29: 7662328 | H29: 16623728 | I29: =SUM(F29:H29) -> 144411836 | J29: =0.86*42.42*E29 -> 237893.91 | K29: =2.5423*E29 -> 16578.338
A30: 44958 | B30: 8012 | C30: 447 | D30: 632 | E30: =SUM(B30:D30) -> 9091 | F30: 180414430 | G30: 9842128 | H30: 12798000 | I30: =SUM(F30:H30) -> 203054558 | J30: =0.86*42.42*E30 -> 331650.59 | K30: =2.5423*E30 -> 23112.049
A31: 44986 | B31: 8298 | C31: 772 | D31: 760 | E31: =SUM(B31:D31) -> 9830 | F31: 173577210 | G31: 16998037 | H31: 15647640 | I31: =SUM(F31:H31) -> 206222887 | J31: =0.86*42.42*E31 -> 358610.2 | K31: =2.5423*E31 -> 24990.809
A32: 45017 | B32: 8491 | C32: 490 | D32: 0 | E32: =SUM(B32:D32) -> 8981 | F32: 169946770 | G32: 10788909 | H32: 0 | I32: =SUM(F32:H32) -> 180735679 | J32: =0.86*42.42*E32 -> 327637.66 | K32: =2.5423*E32 -> 22832.396
A33: 45047 | B33: 5808 | C33: 680 | D33: 0 | E33: =SUM(B33:D33) -> 6488 | F33: 110119480 | G33: 12437200 | H33: 0 | I33: =SUM(F33:H33) -> 122556680 | J33: =0.86*42.42*E33 -> 236690.03 | K33: =2.5423*E33 -> 16494.442
A34: 45078 | B34: 6249 | C34: 680 | D34: 47296 | E34: =SUM(B34:D34) -> 54225 | F34: 114660690 | G34: 12437200 | H34: 865043840 | I34: =SUM(F34:H34) -> 992141730 | J34: =0.86*42.42*E34 -> 1978193.1 | K34: =2.5423*E34 -> 137856.22
A35: 45108 | B35: 5140 | C35: 680 | D35: 55 | E35: =SUM(B35:D35) -> 5875 | F35: 96664607 | G35: 12437200 | H35: 1316880 | I35: =SUM(F35:H35) -> 110418687 | J35: =0.86*42.42*E35 -> 214327.05 | K35: =2.5423*E35 -> 14936.013
A36: 45139 | B36: 8586 | C36: 400 | D36: 625 | E36: =SUM(B36:D36) -> 9611 | F36: 184993370 | G36: 7316000 | H36: 11431250 | I36: =SUM(F36:H36) -> 203740620 | J36: =0.86*42.42*E36 -> 350620.81 | K36: =2.5423*E36 -> 24434.045
A37: 45170 | B37: 10033 | C37: 360 | D37: 927 | E37: =SUM(B37:D37) -> 11320 | F37: 232576940 | G37: 6584400 | H37: 16954830 | I37: =SUM(F37:H37) -> 256116170 | J37: =0.86*42.42*E37 -> 412967.18 | K37: =2.5423*E37 -> 28778.836
A38: 45200 | B38: 9158 | C38: 160 | D38: 226 | E38: =SUM(B38:D38) -> 9544 | F38: 216676390 | G38: 2926400 | H38: 4133540 | I38: =SUM(F38:H38) -> 223736330 | J38: =0.86*42.42*E38 -> 348176.57 | K38: =2.5423*E38 -> 24263.711
A39: 45231 | B39: 9560 | C39: 160 | D39: 4425 | E39: =SUM(B39:D39) -> 14145 | F39: 213094430 | G39: 2926400 | H39: 80933250 | I39: =SUM(F39:H39) -> 296954080 | J39: =0.86*42.42*E39 -> 516026.57 | K39: =2.5423*E39 -> 35960.834
A40: 45261 | B40: 10359 | C40: 160 | D40: 1140 | E40: =SUM(B40:D40) -> 11659 | F40: 210546750 | G40: 2926400 | H40: 20850600 | I40: =SUM(F40:H40) -> 234323750 | J40: =0.86*42.42*E40 -> 425334.31 | K40: =2.5423*E40 -> 29640.676
...

Sheet Tiêu thụ LPG
B2: Tiêu thụ | C2: Chi phí | D2: MJ | E2: kg CO2
A3: 44197 | B3: 36 | C3: 1020000 | D3: =B3*42.5 -> 1530 | E3: =2.6669*B3 -> 96.0084
A4: 44228 | B4: 60 | C4: 1830000 | D4: =B4*42.5 -> 2550 | E4: =2.6669*B4 -> 160.014
A5: 44256 | B5: 72 | C5: 2220000 | D5: =B5*42.5 -> 3060 | E5: =2.6669*B5 -> 192.0168
A6: 44287 | B6: 60 | C6: 1840000 | D6: =B6*42.5 -> 2550 | E6: =2.6669*B6 -> 160.014
A7: 44317 | B7: 72 | C7: 2070000 | D7: =B7*42.5 -> 3060 | E7: =2.6669*B7 -> 192.0168
A8: 44348 | B8: 84 | C8: 2700000 | D8: =B8*42.5 -> 3570 | E8: =2.6669*B8 -> 224.0196
A9: 44378 | B9: 108 | C9: 3600000 | D9: =B9*42.5 -> 4590 | E9: =2.6669*B9 -> 288.0252
A10: 44409 | B10: 96 | C10: 3080000 | D10: =B10*42.5 -> 4080 | E10: =2.6669*B10 -> 256.0224
A11: 44440 | B11: 96 | C11: 3276000 | D11: =B11*42.5 -> 4080 | E11: =2.6669*B11 -> 256.0224
A12: 44470 | B12: 108 | C12: 3874500 | D12: =B12*42.5 -> 4590 | E12: =2.6669*B12 -> 288.0252
A13: 44501 | B13: 120 | C13: 4410000 | D13: =B13*42.5 -> 5100 | E13: =2.6669*B13 -> 320.028
A14: 44531 | B14: 120 | C14: 5166000 | D14: =B14*42.5 -> 5100 | E14: =2.6669*B14 -> 320.028
A15: Tổng cộng 2021 | B15: =SUBTOTAL(9,B3:B14) -> 1032 | C15: =SUBTOTAL(9,C3:C14) -> 35086500 | D15: =SUBTOTAL(9,D3:D14) -> 43860 | E15: =SUBTOTAL(9,E3:E14) -> 2752.2408
A16: 44562 | B16: 120 | C16: 4200000 | D16: =B16*42.5 -> 5100 | E16: =2.6669*B16 -> 320.028
A17: 44593 | B17: 108 | C17: 3780000 | D17: =B17*42.5 -> 4590 | E17: =2.6669*B17 -> 288.0252
A18: 44621 | B18: 228 | C18: 8220000 | D18: =B18*42.5 -> 9690 | E18: =2.6669*B18 -> 608.0532
A19: 44652 | B19: 315 | C19: 11900000 | D19: =B19*42.5 -> 13387.5 | E19: =2.6669*B19 -> 840.0735
A20: 44682 | B20: 360 | C20: 13600000 | D20: =B20*42.5 -> 15300 | E20: =2.6669*B20 -> 960.084
A21: 44713 | B21: 270 | C21: 10200000 | D21: =B21*42.5 -> 11475 | E21: =2.6669*B21 -> 720.063
A22: 44743 | B22: 450 | C22: 16500000 | D22: =B22*42.5 -> 19125 | E22: =2.6669*B22 -> 1200.105
A23: 44774 | B23: 450 | C23: 13800000 | D23: =B23*42.5 -> 19125 | E23: =2.6669*B23 -> 1200.105
A24: 44805 | B24: 465 | C24: 12910000 | D24: =B24*42.5 -> 19762.5 | E24: =2.6669*B24 -> 1240.1085
A25: 44835 | B25: 342 | C25: 8780000 | D25: =B25*42.5 -> 14535 | E25: =2.6669*B25 -> 912.0798
A26: 44866 | B26: 318 | C26: 5800000 | D26: =B26*42.5 -> 13515 | E26: =2.6669*B26 -> 848.0742
A27: 44896 | B27: 486 | C27: 13110000 | D27: =B27*42.5 -> 20655 | E27: =2.6669*B27 -> 1296.1134
A28: Tổng cộng 2022 | B28: =SUBTOTAL(9,B16:B27) -> 3912 | C28: =SUBTOTAL(9,C16:C27) -> 122800000 | D28: =SUBTOTAL(9,D16:D27) -> 166260 | E28: =SUBTOTAL(9,E16:E27) -> 10432.913
A29: 44927 | B29: 350 | C29: 13599825 | D29: =B29*42.5 -> 14875 | E29: =2.6669*B29 -> 933.415
A30: 44958 | B30: 315 | C30: 11900000 | D30: =B30*42.5 -> 13387.5 | E30: =2.6669*B30 -> 840.0735
A31: 44986 | B31: 405 | C31: 12825000 | D31: =B31*42.5 -> 17212.5 | E31: =2.6669*B31 -> 1080.0945
A32: 45017 | B32: 360 | C32: 9750000 | D32: =B32*42.5 -> 15300 | E32: =2.6669*B32 -> 960.084
A33: 45047 | B33: 405 | C33: 10968750 | D33: =B33*42.5 -> 17212.5 | E33: =2.6669*B33 -> 1080.0945
A34: 45078 | B34: 405 | C34: 1462500 | D34: =B34*42.5 -> 17212.5 | E34: =2.6669*B34 -> 1080.0945
A35: 45108 | B35: 360 | C35: 13600000 | D35: =B35*42.5 -> 15300 | E35: =2.6669*B35 -> 960.084
A36: 45139 | B36: 360 | C36: 13600000 | D36: =B36*42.5 -> 15300 | E36: =2.6669*B36 -> 960.084
A37: 45170 | B37: 315 | C37: 11900000 | D37: =B37*42.5 -> 13387.5 | E37: =2.6669*B37 -> 840.0735
A38: 45200 | B38: 315 | C38: 11900000 | D38: =B38*42.5 -> 13387.5 | E38: =2.6669*B38 -> 840.0735
A39: 45231 | B39: 372 | C39: 12745454 | D39: =B39*42.5 -> 15810 | E39: =2.6669*B39 -> 992.0868
A40: 45261 | B40: 360 | C40: 13600000 | D40: =B40*42.5 -> 15300 | E40: =2.6669*B40 -> 960.084
A41: Tổng cộng 2023 | B41: =SUBTOTAL(9,B29:B40) -> 4322 | C41: =SUBTOTAL(9,C29:C40) -> 1.3785153e+08 | D41: =SUBTOTAL(9,D29:D40) -> 183685 | E41: =SUBTOTAL(9,E29:E40) -> 11526.342
...

Sheet Total Energy
B2: Điện | C2: Xăng | D2: DO | E2: LPG | F2: Total | G2: Productivity | H2: STH
A3: 44197 | B3: ='Tiêu thụ điện'!L3 -> 667800 | C3: ='Tiêu thụ xăng'!D2 -> 0 | D3: ='Tiêu thụ DO'!J3 -> 12330.646 | E3: ='Tiêu thụ LPG'!D3 -> 1530 | F3: =SUM(B3:E3) -> 681660.65 | G3: 0
A4: 44228 | B4: ='Tiêu thụ điện'!L4 -> 466200 | C4: ='Tiêu thụ xăng'!D3 -> 98937.674 | D4: ='Tiêu thụ DO'!J4 -> 80003.272 | E4: ='Tiêu thụ LPG'!D4 -> 2550 | F4: =SUM(B4:E4) -> 647690.95 | G4: 0
A5: 44256 | B5: ='Tiêu thụ điện'!L5 -> 743400 | C5: ='Tiêu thụ xăng'!D4 -> 87205.934 | D5: ='Tiêu thụ DO'!J5 -> 46550.011 | E5: ='Tiêu thụ LPG'!D5 -> 3060 | F5: =SUM(B5:E5) -> 880215.95 | G5: 0
A6: 44287 | B6: ='Tiêu thụ điện'!L6 -> 970200 | C6: ='Tiêu thụ xăng'!D5 -> 105781.19 | D6: ='Tiêu thụ DO'!J6 -> 94559.27 | E6: ='Tiêu thụ LPG'!D6 -> 2550 | F6: =SUM(B6:E6) -> 1173090.5 | G6: 0
A7: 44317 | B7: ='Tiêu thụ điện'!L7 -> 919800 | C7: ='Tiêu thụ xăng'!D6 -> 69803.853 | D7: ='Tiêu thụ DO'!J7 -> 130128.44 | E7: ='Tiêu thụ LPG'!D7 -> 3060 | F7: =SUM(B7:E7) -> 1122792.3 | G7: 0
A8: 44348 | B8: ='Tiêu thụ điện'!L8 -> 1398600 | C8: ='Tiêu thụ xăng'!D7 -> 91937.736 | D8: ='Tiêu thụ DO'!J8 -> 122649.79 | E8: ='Tiêu thụ LPG'!D8 -> 3570 | F8: =SUM(B8:E8) -> 1616757.5 | G8: 0
A9: 44378 | B9: ='Tiêu thụ điện'!L9 -> 1549800 | C9: ='Tiêu thụ xăng'!D8 -> 78954.61 | D9: ='Tiêu thụ DO'!J9 -> 157343.42 | E9: ='Tiêu thụ LPG'!D9 -> 4590 | F9: =SUM(B9:E9) -> 1790688 | G9: 0
A10: 44409 | B10: ='Tiêu thụ điện'!L10 -> 1688400 | C10: ='Tiêu thụ xăng'!D9 -> 56898.939 | D10: ='Tiêu thụ DO'!J10 -> 172920.89 | E10: ='Tiêu thụ LPG'!D10 -> 4080 | F10: =SUM(B10:E10) -> 1922299.8 | G10: 0
A11: 44440 | B11: ='Tiêu thụ điện'!L11 -> 1387134 | C11: ='Tiêu thụ xăng'!D10 -> 41647.677 | D11: ='Tiêu thụ DO'!J11 -> 99374.789 | E11: ='Tiêu thụ LPG'!D11 -> 4080 | F11: =SUM(B11:E11) -> 1532236.5 | G11: 0
A12: 44470 | B12: ='Tiêu thụ điện'!L12 -> 1473318 | C12: ='Tiêu thụ xăng'!D11 -> 29524.879 | D12: ='Tiêu thụ DO'!J12 -> 126407.36 | E12: ='Tiêu thụ LPG'!D12 -> 4590 | F12: =SUM(B12:E12) -> 1633840.2 | G12: 0
A13: 44501 | B13: ='Tiêu thụ điện'!L13 -> 1283212.8 | C13: ='Tiêu thụ xăng'!D12 -> 58658.7 | D13: ='Tiêu thụ DO'!J13 -> 273973.81 | E13: ='Tiêu thụ LPG'!D13 -> 5100 | F13: =SUM(B13:E13) -> 1620945.3 | G13: 23289 | H13: =F13/G13 -> 69.601327
A14: 44531 | B14: ='Tiêu thụ điện'!L14 -> 745142.4 | C14: ='Tiêu thụ xăng'!D13 -> 55725.765 | D14: ='Tiêu thụ DO'!J14 -> 357661.68 | E14: ='Tiêu thụ LPG'!D14 -> 5100 | F14: =SUM(B14:E14) -> 1163629.8 | G14: 27099 | H14: =F14/G14 -> 42.939955
A15: Tổng cộng 2021 | B15: ='Tiêu thụ điện'!L15 -> 13293007 | C15: ='Tiêu thụ xăng'!D14 -> 775076.96 | D15: ='Tiêu thụ DO'!J15 -> 1673903.4 | E15: ='Tiêu thụ LPG'!D15 -> 43860 | F15: =SUM(B15:E15) -> 15785848 | G15: =SUBTOTAL(9,G3:G14) -> 50388 | H15: =F15/G15 -> 313.28585
A16: 44562 | B16: ='Tiêu thụ điện'!L16 -> 1602583.2 | C16: ='Tiêu thụ xăng'!D15 -> 60809.519 | D16: ='Tiêu thụ DO'!J16 -> 183390.99 | E16: ='Tiêu thụ LPG'!D16 -> 5100 | F16: =SUM(B16:E16) -> 1851883.7 | G16: 88188 | H16: =F16/G16 -> 20.999271
A17: 44593 | B17: ='Tiêu thụ điện'!L17 -> 1552719.6 | C17: ='Tiêu thụ xăng'!D16 -> 57681.055 | D17: ='Tiêu thụ DO'!J17 -> 107108.8 | E17: ='Tiêu thụ LPG'!D17 -> 4590 | F17: =SUM(B17:E17) -> 1722099.5 | G17: 93437 | H17: =F17/G17 -> 18.430594
A18: 44621 | B18: ='Tiêu thụ điện'!L18 -> 1994972.4 | C18: ='Tiêu thụ xăng'!D17 -> 65736.85 | D18: ='Tiêu thụ DO'!J18 -> 170367.2 | E18: ='Tiêu thụ LPG'!D18 -> 9690 | F18: =SUM(B18:E18) -> 2240766.5 | G18: 187118 | H18: =F18/G18 -> 11.975152
A19: 44652 | B19: ='Tiêu thụ điện'!L19 -> 2857377.6 | C19: ='Tiêu thụ xăng'!D18 -> 121501.72 | D19: ='Tiêu thụ DO'!J19 -> 196414.78 | E19: ='Tiêu thụ LPG'!D19 -> 13387.5 | F19: =SUM(B19:E19) -> 3188681.6 | G19: 308466 | H19: =F19/G19 -> 10.337222
A20: 44682 | B20: ='Tiêu thụ điện'!L20 -> 2990959.2 | C20: ='Tiêu thụ xăng'!D19 -> 167724.78 | D20: ='Tiêu thụ DO'!J20 -> 197034.96 | E20: ='Tiêu thụ LPG'!D20 -> 15300 | F20: =SUM(B20:E20) -> 3371018.9 | G20: 351801 | H20: =F20/G20 -> 9.5821755
A21: 44713 | B21: ='Tiêu thụ điện'!L21 -> 4306957.2 | C21: ='Tiêu thụ xăng'!D20 -> 210271.89 | D21: ='Tiêu thụ DO'!J21 -> 202178.81 | E21: ='Tiêu thụ LPG'!D21 -> 11475 | F21: =SUM(B21:E21) -> 4730882.9 | G21: 453767 | H21: =F21/G21 -> 10.425798
A22: 44743 | B22: ='Tiêu thụ điện'!L22 -> 4594867.2 | C22: ='Tiêu thụ xăng'!D21 -> 183406.2 | D22: ='Tiêu thụ DO'!J22 -> 267626.08 | E22: ='Tiêu thụ LPG'!D22 -> 19125 | F22: =SUM(B22:E22) -> 5065024.5 | G22: 550573 | H22: =F22/G22 -> 9.1995512
A23: 44774 | B23: ='Tiêu thụ điện'!L23 -> 4913035.2 | C23: ='Tiêu thụ xăng'!D22 -> 246953.13 | D23: ='Tiêu thụ DO'!J23 -> 321180.48 | E23: ='Tiêu thụ LPG'!D23 -> 19125 | F23: =SUM(B23:E23) -> 5500293.8 | G23: 700152 | H23: =F23/G23 -> 7.8558567
A24: 44805 | B24: ='Tiêu thụ điện'!L24 -> 4923676.8 | C24: ='Tiêu thụ xăng'!D23 -> 207026.11 | D24: ='Tiêu thụ DO'!J24 -> 341391.07 | E24: ='Tiêu thụ LPG'!D24 -> 19762.5 | F24: =SUM(B24:E24) -> 5491856.5 | G24: 567211 | H24: =F24/G24 -> 9.6822108
A25: 44835 | B25: ='Tiêu thụ điện'!L25 -> 5750892 | C25: ='Tiêu thụ xăng'!D24 -> 172964.95 | D25: ='Tiêu thụ DO'!J25 -> 340041.27 | E25: ='Tiêu thụ LPG'!D25 -> 14535 | F25: =SUM(B25:E25) -> 6278433.2 | G25: 701525 | H25: =F25/G25 -> 8.9496928
A26: 44866 | B26: ='Tiêu thụ điện'!L26 -> 4426884 | C26: ='Tiêu thụ xăng'!D25 -> 143909.34 | D26: ='Tiêu thụ DO'!J26 -> 288201.48 | E26: ='Tiêu thụ LPG'!D26 -> 13515 | F26: =SUM(B26:E26) -> 4872509.8 | G26: 660274 | H26: =F26/G26 -> 7.379527
A27: 44896 | B27: ='Tiêu thụ điện'!L27 -> 3793608 | C27: ='Tiêu thụ xăng'!D26 -> 234204.64 | D27: ='Tiêu thụ DO'!J27 -> 456452.77 | E27: ='Tiêu thụ LPG'!D27 -> 20655 | F27: =SUM(B27:E27) -> 4504920.4 | G27: 657397 | H27: =F27/G27 -> 6.8526635
A28: Tổng cộng 2021 | B28: ='Tiêu thụ điện'!L28 -> 43708532 | C28: ='Tiêu thụ xăng'!D27 -> 1872190.2 | D28: ='Tiêu thụ DO'!J28 -> 3071388.7 | E28: ='Tiêu thụ LPG'!D28 -> 166260 | F28: =SUM(B28:E28) -> 48818371 | G28: =SUBTOTAL(9,G16:G27) -> 5319909 | H28: =F28/G28 -> 9.1765425
A29: 44927 | B29: ='Tiêu thụ điện'!L29 -> 2112012 | C29: ='Tiêu thụ xăng'!D28 -> 117512.93 | D29: ='Tiêu thụ DO'!J29 -> 237893.91 | E29: ='Tiêu thụ LPG'!D29 -> 14875 | F29: =SUM(B29:E29) -> 2482293.8 | G29: 442109 | H29: =F29/G29 -> 5.6146648
A30: 44958 | B30: ='Tiêu thụ điện'!L30 -> 3130848 | C30: ='Tiêu thụ xăng'!D29 -> 216020.44 | D30: ='Tiêu thụ DO'!J30 -> 331650.59 | E30: ='Tiêu thụ LPG'!D30 -> 13387.5 | F30: =SUM(B30:E30) -> 3691906.5 | G30: 621191 | H30: =F30/G30 -> 5.9432711
A31: 44986 | B31: ='Tiêu thụ điện'!L31 -> 4077511.2 | C31: ='Tiêu thụ xăng'!D30 -> 214378 | D31: ='Tiêu thụ DO'!J31 -> 358610.2 | E31: ='Tiêu thụ LPG'!D31 -> 17212.5 | F31: =SUM(B31:E31) -> 4667711.9 | G31: 780207 | H31: =F31/G31 -> 5.9826583
A32: 45017 | B32: ='Tiêu thụ điện'!L32 -> 4423572 | C32: ='Tiêu thụ xăng'!D31 -> 206126.67 | D32: ='Tiêu thụ DO'!J32 -> 327637.66 | E32: ='Tiêu thụ LPG'!D32 -> 15300 | F32: =SUM(B32:E32) -> 4972636.3 | G32: 800208 | H32: =F32/G32 -> 6.2141797
A33: 45047 | B33: ='Tiêu thụ điện'!L33 -> 4175136 | C33: ='Tiêu thụ xăng'!D32 -> 204953.5 | D33: ='Tiêu thụ DO'!J33 -> 236690.03 | E33: ='Tiêu thụ LPG'!D33 -> 17212.5 | F33: =SUM(B33:E33) -> 4633992 | G33: 860646 | H33: =F33/G33 -> 5.3843183
A34: 45078 | B34: ='Tiêu thụ điện'!L34 -> 3556224 | C34: ='Tiêu thụ xăng'!D33 -> 212266.28 | D34: ='Tiêu thụ DO'!J34 -> 1978193.1 | E34: ='Tiêu thụ LPG'!D34 -> 17212.5 | F34: =SUM(B34:E34) -> 5763895.9 | G34: 800166 | H34: =F34/G34 -> 7.2033751
A35: 45108 | B35: ='Tiêu thụ điện'!L35 -> 3958668 | C35: ='Tiêu thụ xăng'!D34 -> 176159.51 | D35: ='Tiêu thụ DO'!J35 -> 214327.05 | E35: ='Tiêu thụ LPG'!D35 -> 15300 | F35: =SUM(B35:E35) -> 4364454.6 | G35: 766156 | H35: =F35/G35 -> 5.6965612
A36: 45139 | B36: ='Tiêu thụ điện'!L36 -> 5079816 | C36: ='Tiêu thụ xăng'!D35 -> 218953.37 | D36: ='Tiêu thụ DO'!J36 -> 350620.81 | E36: ='Tiêu thụ LPG'!D36 -> 15300 | F36: =SUM(B36:E36) -> 5664690.2 | G36: 840154 | H36: =F36/G36 -> 6.7424427
A37: 45170 | B37: ='Tiêu thụ điện'!L37 -> 4695933.6 | C37: ='Tiêu thụ xăng'!D36 -> 246796.7 | D37: ='Tiêu thụ DO'!J37 -> 412967.18 | E37: ='Tiêu thụ LPG'!D37 -> 13387.5 | F37: =SUM(B37:E37) -> 5369085 | G37: 740042 | H37: =F37/G37 -> 7.2551085
A38: 45200 | B38: ='Tiêu thụ điện'!L38 -> 4643326.8 | C38: ='Tiêu thụ xăng'!D37 -> 205305.45 | D38: ='Tiêu thụ DO'!J38 -> 348176.57 | E38: ='Tiêu thụ LPG'!D38 -> 13387.5 | F38: =SUM(B38:E38) -> 5210196.3 | G38: 860065 | H38: =F38/G38 -> 6.05791
A39: 45231 | B39: ='Tiêu thụ điện'!L39 -> 5007744 | C39: ='Tiêu thụ xăng'!D38 -> 226187.95 | D39: ='Tiêu thụ DO'!J39 -> 516026.57 | E39: ='Tiêu thụ LPG'!D39 -> 15810 | F39: =SUM(B39:E39) -> 5765768.5 | G39: 901232 | H39: =F39/G39 -> 6.3976518
A40: 45261 | B40: ='Tiêu thụ điện'!L40 -> 4948272 | C40: ='Tiêu thụ xăng'!D39 -> 222355.58 | D40: ='Tiêu thụ DO'!J40 -> 425334.31 | E40: ='Tiêu thụ LPG'!D40 -> 15300 | F40: =SUM(B40:E40) -> 5611261.9 | G40: 1020188 | H40: =F40/G40 -> 5.5002234
A41: Tổng cộng 2021 | B41: ='Tiêu thụ điện'!L41 -> 49809064 | C41: ='Tiêu thụ xăng'!D40 -> 2467016.4 | D41: ='Tiêu thụ DO'!J41 -> 5738127.9 | E41: ='Tiêu thụ LPG'!D41 -> 183685 | F41: =SUM(B41:E41) -> 58197893 | G41: =SUBTOTAL(9,G29:G40) -> 9432364 | H41: =F41/G41 -> 6.170022
...

Sheet Total Energy cost
B2: Điện | C2: Xăng | D2: DO | E2: LPG | F2: Total | G2: Productivity | H2: STH
A3: 44197 | B3: ='Tiêu thụ điện'!I3 -> 355624500 | C3: ='Tiêu thụ xăng'!C2 -> 0 | D3: ='Tiêu thụ DO'!I3 -> 5742000 | E3: ='Tiêu thụ LPG'!C3 -> 1020000 | F3: =SUM(B3:E3) -> 362386500 | G3: 0
A4: 44228 | B4: ='Tiêu thụ điện'!I4 -> 240908500 | C4: ='Tiêu thụ xăng'!C3 -> 43007371 | D4: ='Tiêu thụ DO'!I4 -> 37227769 | E4: ='Tiêu thụ LPG'!C4 -> 1830000 | F4: =SUM(B4:E4) -> 322973640 | G4: 0
A5: 44256 | B5: ='Tiêu thụ điện'!I5 -> 395573500 | C5: ='Tiêu thụ xăng'!C4 -> 32183500 | D5: ='Tiêu thụ DO'!I5 -> 24289815 | E5: ='Tiêu thụ LPG'!C5 -> 2220000 | F5: =SUM(B5:E5) -> 454266815 | G5: 0
A6: 44287 | B6: ='Tiêu thụ điện'!I6 -> 525780500 | C6: ='Tiêu thụ xăng'!C5 -> 39140600 | D6: ='Tiêu thụ DO'!I6 -> 44023450 | E6: ='Tiêu thụ LPG'!C6 -> 1840000 | F6: =SUM(B6:E6) -> 610784550 | G6: 0
A7: 44317 | B7: ='Tiêu thụ điện'!I7 -> 504010500 | C7: ='Tiêu thụ xăng'!C6 -> 32097100 | D7: ='Tiêu thụ DO'!I7 -> 51141200 | E7: ='Tiêu thụ LPG'!C7 -> 2070000 | F7: =SUM(B7:E7) -> 589318800 | G7: 0
A8: 44348 | B8: ='Tiêu thụ điện'!I8 -> 766867500 | C8: ='Tiêu thụ xăng'!C7 -> 44872431 | D8: ='Tiêu thụ DO'!I8 -> 51372920 | E8: ='Tiêu thụ LPG'!C8 -> 2700000 | F8: =SUM(B8:E8) -> 865812851 | G8: 0
A9: 44378 | B9: ='Tiêu thụ điện'!I9 -> 847913500 | C9: ='Tiêu thụ xăng'!C8 -> 41975651 | D9: ='Tiêu thụ DO'!I9 -> 69452248 | E9: ='Tiêu thụ LPG'!C9 -> 3600000 | F9: =SUM(B9:E9) -> 962941399 | G9: 0
A10: 44409 | B10: ='Tiêu thụ điện'!I10 -> 930811000 | C10: ='Tiêu thụ xăng'!C9 -> 27838500 | D10: ='Tiêu thụ DO'!I10 -> 77409525 | E10: ='Tiêu thụ LPG'!C10 -> 3080000 | F10: =SUM(B10:E10) -> 1039139025 | G10: 0
A11: 44440 | B11: ='Tiêu thụ điện'!I11 -> 737433445 | C11: ='Tiêu thụ xăng'!C10 -> 23115450 | D11: ='Tiêu thụ DO'!I11 -> 44354760 | E11: ='Tiêu thụ LPG'!C11 -> 3276000 | F11: =SUM(B11:E11) -> 808179655 | G11: 0
A12: 44470 | B12: ='Tiêu thụ điện'!I12 -> 778762285 | C12: ='Tiêu thụ xăng'!C11 -> 28177334 | D12: ='Tiêu thụ DO'!I12 -> 58882136 | E12: ='Tiêu thụ LPG'!C12 -> 3874500 | F12: =SUM(B12:E12) -> 869696255 | G12: 0
A13: 44501 | B13: ='Tiêu thụ điện'!I13 -> 682691156 | C13: ='Tiêu thụ xăng'!C12 -> 37692000 | D13: ='Tiêu thụ DO'!I13 -> 1.3348195e+08 | E13: ='Tiêu thụ LPG'!C13 -> 4410000 | F13: =SUM(B13:E13) -> 8.582751e+08 | G13: 23289 | H13: =F13/G13 -> 36853.24
A14: 44531 | B14: ='Tiêu thụ điện'!I14 -> 395679676 | C14: ='Tiêu thụ xăng'!C13 -> 30959319 | D14: ='Tiêu thụ DO'!I14 -> 165553225 | E14: ='Tiêu thụ LPG'!C14 -> 5166000 | F14: =SUM(B14:E14) -> 597358220 | G14: 27099 | H14: =F14/G14 -> 22043.552
A15: Tổng cộng 2021 | B15: ='Tiêu thụ điện'!I15 -> 7162056062 | C15: ='Tiêu thụ xăng'!C14 -> 381059256 | D15: ='Tiêu thụ DO'!I15 -> 7.6293099e+08 | E15: ='Tiêu thụ LPG'!C15 -> 35086500 | F15: =SUM(B15:E15) -> 8.3411328e+09 | G15: =SUBTOTAL(9,G3:G14) -> 50388
A16: 44562 | B16: ='Tiêu thụ điện'!I16 -> 850715030 | C16: ='Tiêu thụ xăng'!C15 -> 37401850 | D16: ='Tiêu thụ DO'!I16 -> 90870232 | E16: ='Tiêu thụ LPG'!C16 -> 4200000 | F16: =SUM(B16:E16) -> 983187112 | G16: 88188 | H16: =F16/G16 -> 11148.763
A17: 44593 | B17: ='Tiêu thụ điện'!I17 -> 827191453 | C17: ='Tiêu thụ xăng'!C16 -> 37736600 | D17: ='Tiêu thụ DO'!I17 -> 58739480 | E17: ='Tiêu thụ LPG'!C17 -> 3780000 | F17: =SUM(B17:E17) -> 927447533 | G17: 93437 | H17: =F17/G17 -> 9925.913
A18: 44621 | B18: ='Tiêu thụ điện'!I18 -> 1071671566 | C18: ='Tiêu thụ xăng'!C17 -> 48466380 | D18: ='Tiêu thụ DO'!I18 -> 105314370 | E18: ='Tiêu thụ LPG'!C18 -> 8220000 | F18: =SUM(B18:E18) -> 1233672316 | G18: 187118 | H18: =F18/G18 -> 6593.0179
A19: 44652 | B19: ='Tiêu thụ điện'!I19 -> 1507578979 | C19: ='Tiêu thụ xăng'!C18 -> 87871630 | D19: ='Tiêu thụ DO'!I19 -> 125961515 | E19: ='Tiêu thụ LPG'!C19 -> 11900000 | F19: =SUM(B19:E19) -> 1733312124 | G19: 308466 | H19: =F19/G19 -> 5619.1351
A20: 44682 | B20: ='Tiêu thụ điện'!I20 -> 1529463766 | C20: ='Tiêu thụ xăng'!C19 -> 128035910 | D20: ='Tiêu thụ DO'!I20 -> 129884945 | E20: ='Tiêu thụ LPG'!C20 -> 13600000 | F20: =SUM(B20:E20) -> 1800984621 | G20: 351801 | H20: =F20/G20 -> 5119.3277
A21: 44713 | B21: ='Tiêu thụ điện'!I21 -> 2222718995 | C21: ='Tiêu thụ xăng'!C20 -> 174510950 | D21: ='Tiêu thụ DO'!I21 -> 145755020 | E21: ='Tiêu thụ LPG'!C21 -> 10200000 | F21: =SUM(B21:E21) -> 2553184965 | G21: 453767 | H21: =F21/G21 -> 5626.6431
A22: 44743 | B22: ='Tiêu thụ điện'!I22 -> 2371274528 | C22: ='Tiêu thụ xăng'!C21 -> 145391240 | D22: ='Tiêu thụ DO'!I22 -> 192401517 | E22: ='Tiêu thụ LPG'!C22 -> 16500000 | F22: =SUM(B22:E22) -> 2725567285 | G22: 550573 | H22: =F22/G22 -> 4950.4194
A23: 44774 | B23: ='Tiêu thụ điện'!I23 -> 2497358402 | C23: ='Tiêu thụ xăng'!C22 -> 162969930 | D23: ='Tiêu thụ DO'!I23 -> 211666896 | E23: ='Tiêu thụ LPG'!C23 -> 13800000 | F23: =SUM(B23:E23) -> 2885795228 | G23: 700152 | H23: =F23/G23 -> 4121.6696
A24: 44805 | B24: ='Tiêu thụ điện'!I24 -> 2455712056 | C24: ='Tiêu thụ xăng'!C23 -> 128071900 | D24: ='Tiêu thụ DO'!I24 -> 227942478 | E24: ='Tiêu thụ LPG'!C24 -> 12910000 | F24: =SUM(B24:E24) -> 2824636434 | G24: 567211 | H24: =F24/G24 -> 4979.8689
A25: 44835 | B25: ='Tiêu thụ điện'!I25 -> 2846446050 | C25: ='Tiêu thụ xăng'!C24 -> 99890860 | D25: ='Tiêu thụ DO'!I25 -> 220630875 | E25: ='Tiêu thụ LPG'!C25 -> 8780000 | F25: =SUM(B25:E25) -> 3175747785 | G25: 701525 | H25: =F25/G25 -> 4526.9203
A26: 44866 | B26: ='Tiêu thụ điện'!I26 -> 2182584670 | C26: ='Tiêu thụ xăng'!C25 -> 85628820 | D26: ='Tiêu thụ DO'!I26 -> 194415616 | E26: ='Tiêu thụ LPG'!C26 -> 5800000 | F26: =SUM(B26:E26) -> 2468429106 | G26: 660274 | H26: =F26/G26 -> 3738.4921
A27: 44896 | B27: ='Tiêu thụ điện'!I27 -> 1806269500 | C27: ='Tiêu thụ xăng'!C26 -> 137278860 | D27: ='Tiêu thụ DO'!I27 -> 260698750 | E27: ='Tiêu thụ LPG'!C27 -> 13110000 | F27: =SUM(B27:E27) -> 2217357110 | G27: 657397 | H27: =F27/G27 -> 3372.9346
A28: Tổng cộng 2021 | B28: ='Tiêu thụ điện'!I28 -> 22168984995 | C28: ='Tiêu thụ xăng'!C27 -> 1273254930 | D28: ='Tiêu thụ DO'!I28 -> 1964281694 | E28: ='Tiêu thụ LPG'!C28 -> 122800000 | F28: =SUM(B28:E28) -> 25529321619 | G28: =SUBTOTAL(9,G16:G27) -> 5319909 | H28: =F28/G28 -> 4798.8268
A29: 44927 | B29: ='Tiêu thụ điện'!I29 -> 1017484370 | C29: ='Tiêu thụ xăng'!C28 -> 66743350 | D29: ='Tiêu thụ DO'!I29 -> 144411836 | E29: ='Tiêu thụ LPG'!C29 -> 13599825 | F29: =SUM(B29:E29) -> 1242239381 | G29: 442109 | H29: =F29/G29 -> 2809.8034
A30: 44958 | B30: ='Tiêu thụ điện'!I30 -> 1543754800 | C30: ='Tiêu thụ xăng'!C29 -> 129692860 | D30: ='Tiêu thụ DO'!I30 -> 203054558 | E30: ='Tiêu thụ LPG'!C30 -> 11900000 | F30: =SUM(B30:E30) -> 1888402218 | G30: 621191 | H30: =F30/G30 -> 3039.9703
A31: 44986 | B31: ='Tiêu thụ điện'!I31 -> 2032675960 | C31: ='Tiêu thụ xăng'!C30 -> 131043790 | D31: ='Tiêu thụ DO'!I31 -> 206222887 | E31: ='Tiêu thụ LPG'!C31 -> 12825000 | F31: =SUM(B31:E31) -> 2382767637 | G31: 780207 | H31: =F31/G31 -> 3054.0198
A32: 45017 | B32: ='Tiêu thụ điện'!I32 -> 2217463150 | C32: ='Tiêu thụ xăng'!C31 -> 126110900 | D32: ='Tiêu thụ DO'!I32 -> 180735679 | E32: ='Tiêu thụ LPG'!C32 -> 9750000 | F32: =SUM(B32:E32) -> 2534059729 | G32: 800208 | H32: =F32/G32 -> 3166.7513
A33: 45047 | B33: ='Tiêu thụ điện'!I33 -> 2185763510 | C33: ='Tiêu thụ xăng'!C32 -> 119558890 | D33: ='Tiêu thụ DO'!I33 -> 122556680 | E33: ='Tiêu thụ LPG'!C33 -> 10968750 | F33: =SUM(B33:E33) -> 2438847830 | G33: 860646 | H33: =F33/G33 -> 2833.741
A34: 45078 | B34: ='Tiêu thụ điện'!I34 -> 1821986880 | C34: ='Tiêu thụ xăng'!C33 -> 120989200 | D34: ='Tiêu thụ DO'!I34 -> 992141730 | E34: ='Tiêu thụ LPG'!C34 -> 1462500 | F34: =SUM(B34:E34) -> 2936580310 | G34: 800166 | H34: =F34/G34 -> 3669.9639
A35: 45108 | B35: ='Tiêu thụ điện'!I35 -> 2171488620 | C35: ='Tiêu thụ xăng'!C34 -> 99673480 | D35: ='Tiêu thụ DO'!I35 -> 110418687 | E35: ='Tiêu thụ LPG'!C35 -> 13600000 | F35: =SUM(B35:E35) -> 2395180787 | G35: 766156 | H35: =F35/G35 -> 3126.2312
A36: 45139 | B36: ='Tiêu thụ điện'!I36 -> 2610194370 | C36: ='Tiêu thụ xăng'!C35 -> 134956180 | D36: ='Tiêu thụ DO'!I36 -> 203740620 | E36: ='Tiêu thụ LPG'!C36 -> 13600000 | F36: =SUM(B36:E36) -> 2962491170 | G36: 840154 | H36: =F36/G36 -> 3526.1287
A37: 45170 | B37: ='Tiêu thụ điện'!I37 -> 2436001470 | C37: ='Tiêu thụ xăng'!C36 -> 159837320 | D37: ='Tiêu thụ DO'!I37 -> 256116170 | E37: ='Tiêu thụ LPG'!C37 -> 11900000 | F37: =SUM(B37:E37) -> 2.863855e+09 | G37: 740042 | H37: =F37/G37 -> 3869.8546
A38: 45200 | B38: ='Tiêu thụ điện'!I38 -> 2740529120 | C38: ='Tiêu thụ xăng'!C37 -> 131214940 | D38: ='Tiêu thụ DO'!I38 -> 223736330 | E38: ='Tiêu thụ LPG'!C38 -> 11900000 | F38: =SUM(B38:E38) -> 3.1073804e+09 | G38: 860065 | H38: =F38/G38 -> 3612.9599
A39: 45231 | B39: ='Tiêu thụ điện'!I39 -> 2670431540 | C39: ='Tiêu thụ xăng'!C38 -> 139811800 | D39: ='Tiêu thụ DO'!I39 -> 296954080 | E39: ='Tiêu thụ LPG'!C39 -> 12745454 | F39: =SUM(B39:E39) -> 3.1199429e+09 | G39: 901232 | H39: =F39/G39 -> 3461.8643
A40: 45261 | B40: ='Tiêu thụ điện'!I40 -> 2669665460 | C40: ='Tiêu thụ xăng'!C39 -> 130606320 | D40: ='Tiêu thụ DO'!I40 -> 234323750 | E40: ='Tiêu thụ LPG'!C40 -> 13600000 | F40: =SUM(B40:E40) -> 3048195530 | G40: 1020188 | H40: =F40/G40 -> 2987.8763
A41: Tổng cộng 2021 | B41: ='Tiêu thụ điện'!I41 -> 26117439250 | C41: ='Tiêu thụ xăng'!D40 -> 2467016.4 | D41: ='Tiêu thụ DO'!I41 -> 3174413007 | E41: ='Tiêu thụ LPG'!C41 -> 1.3785153e+08 | F41: =SUM(B41:E41) -> 2.9432171e+10 | G41: =SUBTOTAL(9,G29:G40) -> 9432364 | H41: =F41/G41 -> 3120.3387
...

Sheet Total Emission
B2: Điện | C2: Xăng | D2: DO | E2: LPG | F2: Total | G2: Productivity | H2: STH
A3: 44197 | B3: 125509.3 | C3: 0 | D3: 859.2974 | E3: 96.0084 | F3: =SUM(B3:E3) -> 126464.61 | G3: 0
A4: 44228 | B4: 87619.7 | C4: 7039.219 | D4: 5575.2639 | E4: 160.014 | F4: =SUM(B4:E4) -> 100394.2 | G4: 0
A5: 44256 | B5: 139717.9 | C5: 6204.529 | D5: 3243.9748 | E5: 192.0168 | F5: =SUM(B5:E5) -> 149358.42 | G5: 0
A6: 44287 | B6: 182343.7 | C6: 7526.1215 | D6: 6589.6416 | E6: 160.014 | F6: =SUM(B6:E6) -> 196619.48 | G6: 0
A7: 44317 | B7: 172871.3 | C7: 4966.4055 | D7: 9068.3841 | E7: 192.0168 | F7: =SUM(B7:E7) -> 187098.11 | G7: 0
A8: 44348 | B8: 262859.1 | C8: 6541.1873 | D8: 8547.2126 | E8: 224.0196 | F8: =SUM(B8:E8) -> 278171.52 | G8: 0
A9: 44378 | B9: 291276.3 | C9: 5617.4637 | D9: 10964.94 | E9: 288.0252 | F9: =SUM(B9:E9) -> 308146.73 | G9: 0
A10: 44409 | B10: 317325.4 | C10: 4048.2465 | D10: 12050.502 | E10: 256.0224 | F10: =SUM(B10:E10) -> 333680.17 | G10: 0
A11: 44440 | B11: 260704.13 | C11: 2963.1495 | D11: 6925.2252 | E11: 256.0224 | F11: =SUM(B11:E11) -> 270848.53 | G11: 0
A12: 44470 | B12: 276901.93 | C12: 2100.6365 | D12: 8809.0695 | E12: 288.0252 | F12: =SUM(B12:E12) -> 288099.66 | G12: 0
A13: 44501 | B13: 241172.72 | C13: 4173.45 | D13: 19092.673 | E13: 320.028 | F13: =SUM(B13:E13) -> 264758.87 | G13: 23289 | H13: =F13/G13 -> 11.368409
A14: 44531 | B14: 140045.37 | C14: 3964.7775 | D14: 24924.709 | E14: 320.028 | F14: =SUM(B14:E14) -> 169254.89 | G14: 27099 | H14: =F14/G14 -> 6.2457983
A15: Tổng cộng 2021 | B15: 2498346.9 | C15: 55145.186 | D15: 116650.89 | E15: 2752.2408 | F15: =SUM(B15:E15) -> 2672895.2 | G15: =SUBTOTAL(9,G3:G14) -> 50388 | H15: =F15/G15 -> 53.046264
A16: 44562 | B16: 301196.61 | C16: 4326.4765 | D16: 12780.142 | E16: 320.028 | F16: =SUM(B16:E16) -> 318623.26 | G16: 88188 | H16: =F16/G16 -> 3.6130001
A17: 44593 | B17: 291825.02 | C17: 4103.8925 | D17: 7464.1928 | E17: 288.0252 | F17: =SUM(B17:E17) -> 303681.13 | G17: 93437 | H17: =F17/G17 -> 3.2501165
A18: 44621 | B18: 374943.98 | C18: 4677.0463 | D18: 11872.541 | E18: 608.0532 | F18: =SUM(B18:E18) -> 392101.62 | G18: 187118 | H18: =F18/G18 -> 2.0954778
A19: 44652 | B19: 537028.25 | C19: 8644.6061 | D19: 13687.743 | E19: 840.0735 | F19: =SUM(B19:E19) -> 560200.67 | G19: 308466 | H19: =F19/G19 -> 1.8160856
A20: 44682 | B20: 562134.17 | C20: 11933.285 | D20: 13730.962 | E20: 960.084 | F20: =SUM(B20:E20) -> 588758.5 | G20: 351801 | H20: =F20/G20 -> 1.6735555
A21: 44713 | B21: 809468.68 | C21: 14960.427 | D21: 14089.427 | E21: 720.063 | F21: =SUM(B21:E21) -> 839238.59 | G21: 453767 | H21: =F21/G21 -> 1.8494923
A22: 44743 | B22: 863579.76 | C22: 13048.987 | D22: 18650.313 | E22: 1200.105 | F22: =SUM(B22:E22) -> 896479.17 | G22: 550573 | H22: =F22/G22 -> 1.6282658
A23: 44774 | B23: 923377.67 | C23: 17570.225 | D23: 22382.409 | E23: 1200.105 | F23: =SUM(B23:E23) -> 964530.41 | G23: 700152 | H23: =F23/G23 -> 1.3776014
A24: 44805 | B24: 925377.7 | C24: 14729.496 | D24: 23790.843 | E24: 1240.1085 | F24: =SUM(B24:E24) -> 965138.15 | G24: 567211 | H24: =F24/G24 -> 1.7015505
A25: 44835 | B25: 1080848.2 | C25: 12306.113 | D25: 23696.778 | E25: 912.0798 | F25: =SUM(B25:E25) -> 1117763.2 | G25: 701525 | H25: =F25/G25 -> 1.5933333
A26: 44866 | B26: 832008.25 | C26: 10238.864 | D26: 20084.17 | E26: 848.0742 | F26: =SUM(B26:E26) -> 863179.36 | G26: 660274 | H26: =F26/G26 -> 1.3073048
A27: 44896 | B27: 712987.55 | C27: 16663.195 | D27: 31809.258 | E27: 1296.1134 | F27: =SUM(B27:E27) -> 762756.11 | G27: 657397 | H27: =F27/G27 -> 1.1602671
A28: Tổng cộng 2021 | B28: 8214775.8 | C28: 133202.61 | D28: 214038.78 | E28: 10432.913 | F28: =SUM(B28:E28) -> 8572450.1 | G28: =SUBTOTAL(9,G16:G27) -> 5319909 | H28: =F28/G28 -> 1.6113904
A29: 44927 | B29: 396940.92 | C29: 8360.8115 | D29: 16578.338 | E29: 933.415 | F29: =SUM(B29:E29) -> 422813.49 | G29: 442109 | H29: =F29/G29 -> 0.95635576
A30: 44958 | B30: 588425.49 | C30: 15369.425 | D30: 23112.049 | E30: 840.0735 | F30: =SUM(B30:E30) -> 627747.04 | G30: 621191 | H30: =F30/G30 -> 1.010554
A31: 44986 | B31: 766345.58 | C31: 15252.569 | D31: 24990.809 | E31: 1080.0945 | F31: =SUM(B31:E31) -> 807669.05 | G31: 780207 | H31: =F31/G31 -> 1.0351984
A32: 45017 | B32: 831385.78 | C32: 14665.503 | D32: 22832.396 | E32: 960.084 | F32: =SUM(B32:E32) -> 869843.77 | G32: 800208 | H32: =F32/G32 -> 1.0870221
A33: 45047 | B33: 784693.62 | C33: 14582.034 | D33: 16494.442 | E33: 1080.0945 | F33: =SUM(B33:E33) -> 816850.19 | G33: 860646 | H33: =F33/G33 -> 0.94911286
A34: 45078 | B34: 668372.54 | C34: 15102.324 | D34: 137856.22 | E34: 1080.0945 | F34: =SUM(B34:E34) -> 822411.18 | G34: 800166 | H34: =F34/G34 -> 1.0278007
A35: 45108 | B35: 744009.66 | C35: 12533.399 | D35: 14936.013 | E35: 960.084 | F35: =SUM(B35:E35) -> 772439.15 | G35: 766156 | H35: =F35/G35 -> 1.0082009
A36: 45139 | B36: 954723.2 | C36: 15578.098 | D36: 24434.045 | E36: 960.084 | F36: =SUM(B36:E36) -> 995695.42 | G36: 840154 | H36: =F36/G36 -> 1.1851344
A37: 45170 | B37: 882574.63 | C37: 17559.095 | D37: 28778.836 | E37: 840.0735 | F37: =SUM(B37:E37) -> 929752.64 | G37: 740042 | H37: =F37/G37 -> 1.2563512
A38: 45200 | B38: 872687.48 | C38: 14607.075 | D38: 24263.711 | E38: 840.0735 | F38: =SUM(B38:E38) -> 912398.34 | G38: 860065 | H38: =F38/G38 -> 1.0608481
A39: 45231 | B39: 941177.66 | C39: 16092.823 | D39: 35960.834 | E39: 992.0868 | F39: =SUM(B39:E39) -> 994223.41 | G39: 901232 | H39: =F39/G39 -> 1.1031825
A40: 45261 | B40: 930000.23 | C40: 15820.158 | D40: 29640.676 | E40: 960.084 | F40: =SUM(B40:E40) -> 976421.15 | G40: 1020188 | H40: =F40/G40 -> 0.95709923
A41: Tổng cộng 2021 | B41: 9361336.8 | C41: 175523.32 | D41: 399878.37 | E41: 11526.342 | F41: =SUM(B41:E41) -> 9948264.8 | G41: =SUBTOTAL(9,G29:G40) -> 9432364 | H41: =F41/G41 -> 1.0546948
...

Sheet P01
A1: HỆ THỐNG QUẢN LÝ NĂNG LƯỢNG THÔNG MINH
A2: PHÂN TÍCH LỢI ÍCH CHI PHÍ
A3: Stt | B3: Thông tin | C3: Đơn vị | D3: Giá trị
A4: 1 | B4: Tổng điện năng iêu thụ năm 2023 | C4: kWh | D4: ='Tiêu thụ điện'!$E$41 -> 13835851
A5: 2 | B5: Tỷ lệ điện năng có thể tiết kiệm được | C5: % | D5: 0.015
A6: 3 | B6: Suất tiêu hao điện năng năm 2023 | C6: kWh/đôi | D6: =D4*D5 -> 207537.76
A7: 4 | B7: Mục tiêu STH điện năng năm 2024 | C7: kWh/đôi | D7: 1.35
A8: 5 | B8: Lượng điện sử dụng trong năm 2023 | C8: kWh | D8: 13835851
A9: 6 | B9: Lượng điện tiết kiệm được trong năm | C9: kWh | D9: 207538
A10: 7 | B10: Đơn giá điện bình quân năm 2023 | C10: VNĐ/kWh | D10: ='Tiêu thụ điện'!$J$41 -> 1887.6641
A11: 8 | B11: Số tiền tiết kiệm được | C11: 103 VNĐ | D11: =D9*D10/1000 -> 391762.03
A12: 9 | B12: Chi phí đầu tư dự kiến | C12: 103 VNĐ | D12: 1000000
A13: 10 | B13: Thời gian hoàn vốn giản đơn | C13: tháng | D13: =D12/D11*12 -> 30.63084
A14: 11 | B14: Giảm phát thải CO2 | C14: Kg CO2e | D14: =D9*0.6766 -> 140420.21 | H14: =D12*-1 -> -1000000
A15: 12 | B15: Suất thu lợi nội tại (IRR) | C15: % | D15: =G15 -> 0.27590097 | F15: IRR | G15: =IRR(H14:H19,10%) -> 0.27590097 | H15: =D11 -> 391762.03
A16: 13 | B16: Giá trị hiện tại thuần (NPV) 5 năm 15% | C16: 103đ | D16: =G16 -> 272388.78 | F16: NPV | G16: =NPV(15%,H14:H19) -> 272388.78 | H16: =H15 -> 391762.03
H17: =H16 -> 391762.03
H18: =H17 -> 391762.03
H19: =H18 -> 391762.03

Sheet P02
A1: CHUYỂN LÀM VIỆC GIỜ CAO ĐIỂM SANG GIỜ BÌNH THƯỜNG
A2: PHÂN TÍCH LỢI ÍCH CHI PHÍ
A3: Stt | B3: Thông tin | C3: Đơn vị | D3: Giá trị
A4: 1 | B4: Tỷ lệ điện năng có thể chuyển từ giờ cao điểm sang giờ bình thường | C4: % | D4: 0.02
A5: 2 | B5: Lượng điện sử dụng trong năm 2023 | C5: kWh | D5: ='Tiêu thụ điện'!E41 -> 13835851
A6: 3 | B6: Lượng điện tiết kiệm được trong năm | C6: kWh | D6: =D5*D4 -> 276717.02
A7: 4 | B7: Mục tiêu STH điện năng năm 2024 | C7: VNĐ/kWh | D7: ='Tiêu thụ điện'!$G$42 -> 2883.2518
A8: 5 | B8: Đơn giá điện giờ bình thường bình quân năm 2023 | C8: VNĐ/kWh | D8: ='Tiêu thụ điện'!$F$42 -> 1674.7773
A9: 6 | B9: Chênh lệch đơn giá điện bình quân năm 2023 giờ Cao điểm và giờ bình thường | C9: VNĐ/kWh | D9: =D7-D8 -> 1208.4745
A10: 7 | B10: Số tiền tiết kiệm được | C10: 103 VNĐ | D10: =D6*D9/1000 -> 334405.45
A11: 8 | B11: Chi phí đầu tư dự kiến | C11: 103 VNĐ | D11: 0
A12: 9 | B12: Thời gian hoàn vốn giản đơn | C12: tháng | D12: =D11/D10*12 -> 0
A13: 10 | B13: Giảm phát thải CO2 | C13: Kg CO2e | D13: =D6*0.6766 -> 187226.74 | H13: =D11*-1 -> 0
A14: 11 | B14: Suất thu lợi nội tại (IRR) | C14: % | D14: =G14 -> #NUM! | F14: IRR | G14: =IRR(H13:H18,10%) -> #NUM! | H14: =D10 -> 334405.45
A15: 12 | B15: Giá trị hiện tại thuần (NPV) 5 năm 15% | C15: 103đ | D15: =G15 -> 974764.29 | F15: NPV | G15: =NPV(15%,H13:H18) -> 974764.29 | H15: =H14 -> 334405.45
H16: =H15 -> 334405.45
H17: =H16 -> 334405.45
H18: =H17 -> 334405.45

Sheet P03
A1: LẮP ĐẶT HỆ THỐNG ĐIỆN NLMT Á MÁI
A2: PHÂN TÍCH LỢI ÍCH CHI PHÍ
A3: Stt | B3: Thông tin | C3: Đơn vị | D3: Giá trị
A4: 1 | B4: Điện năng dự kiến phát hàng năm | C4: kWh | D4: 4161600
A5: 2 | B5: Đơn giá điện bình quân năm 2023 | C5: VNĐ/kWh | D5: ='Tiêu thụ điện'!$J$41 -> 1887.6641
A6: 3 | B6: Số tiền tiết kiệm được | C6: 103 VNĐ | D6: =D4*D5/1000 -> 7855702.9
A7: 4 | B7: Mục tiêu STH điện năng năm 2024 | C7: 103 VNĐ | D7: 45000000
A8: 5 | B8: Thời gian hoàn vốn giản đơn | C8: tháng | D8: =D7/D6*12 -> 68.73987
A9: 6 | B9: Giảm phát thải CO2 | C9: Kg CO2e | D9: =D4*0.6766 -> 2815738.6 | H9: =D7*-1 -> -45000000
A10: 7 | B10: Suất thu lợi nội tại (IRR) | C10: % | D10: =G10 -> 0.11665985 | F10: IRR | G10: =IRR(H9:H19,10%) -> 0.11665985 | H10: =D6 -> 7855702.9
